Workbook

Sheet 0731-1
B1: 일일자금계획 | F1: 담 당 | G1: 차 장 | H1: 실 장 | I1: 담 당 임 원
B3: 주식회사 카탈리스터 | F3: 작성일자 | G3: 문서번호 | H3: 작성자 | I3: 보존연한
F4: 2026-07-31(1) | G4: 전략금융실-260731(1) | H4: 임정하 | I4: 3년
B6: 1. 일일자금수지 실적 | K6: 컴투버스 급여이체 담당자
A7: 계정과목 | B7: 통화구분 | C7: 거래처명 | D7: 내 역 | F7: 수입 | G7: 지출 | H7: 계좌 | I7: 비고 | K7: 하나은행 가산디지털지점 권은지 계장 02-852-1111(103)
A8: 외상매출금 | B8: 1)원화 | C8: 컴투스플랫폼 | D8: 서버비 정산금(7/31) | F8: 56328 | H8: 하나004
E40: 소계(￦) | F40: =SUM(F8:F39) -> 56328 | G40: =SUM(G8:G39) -> 0
B41: 2) 외화(USD)
E43: 소계(U$) | F43: =SUM(F41:F42) -> 0 | G43: =SUM(G41:G42) -> 0
B45: 2. 일일자금수지 계획 | K45: ※ 실적, 계획 수지항목 = 외부로부터의 입출금내역만 기재.(보통예금, 자금대체 기재는 따로)
A46: 계정과목 | B46: 통화구분 | C46: 거래처명 | D46: 내 역 | F46: 수입 | G46: 지출 | H46: 계좌 | I46: 비고
B47: 1) 원화
E99: 소계(￦) | F99: =SUM(F47:F98) -> 0 | G99: =SUM(G47:G98) -> 0
B100: 2) 외화(USD)
E104: 소계(U$) | F104: =SUM(F100:F103) -> 0 | G104: =SUM(G100:G103) -> 0
B105: 2-1. 자금대체
B106: 1) 원화 수시입출 예금 | D106: ` | I106: (단위: 원)
B107: 통화구분 | C107: 거래처명 | D107: 내 역 | F107: 수입 | G107: 지출 | H107: 계좌 | I107: 비고
E113: 소계(￦) | F113: =SUM(F108:F112) -> 0 | G113: =SUM(G108:G112) -> 0
B115: 3. 자금현황
B116: 1) 원화 수시입출 예금 | D116: ` | I116: (단위: 원)
B117: 은행 | C117: 계좌번호 | E117: 전일 잔액 | F117: 차변(입금) | G117: 대변(출금) | H117: 당일잔액 | I117: 비고
B118: 하나은행 | C118: 332-910058-20004 | D118: 보통예금 | E118: 115935 | F118: =SUMIF($H$47:$H$99,J118,$F$47:$F$99)+SUMIF($H$107:$H$113,J118,$F$107:$F$113) -> 0 | G118: =SUMIF($H$47:$H$99,J118,$G$47:$G$99)+SUMIF($H$107:$H$113,J118,$G$107:$G$113) -> 0 | H118: =E118+F118-G118 -> 115935 | I118: 연구개발과제 | J118: 하나004
B119: 하나은행 | C119: 332-910052-92404 | D119: MMDA | E119: 297485654 | F119: =SUMIF($H$47:$H$98,J119,$F$47:$F$98)+F113 -> 0 | G119: =SUMIF($H$47:$H$98,J119,$G$47:$G$98) -> 0 | H119: =E119+F119-G119 -> 297485654 | I119: 운영자금 | J119: 하나404
B120: 하나은행 | C120: 332-910055-98704 | D120: MMDA | E120: 78020 | F120: =SUMIF($H$47:$H$98,J120,$F$47:$F$98)+SUMIF($H$107:$H$113,J120,$F$107:$F$113) -> 0 | G120: =SUMIF($H$47:$H$98,J120,$G$47:$G$98)+SUMIF($H$107:$H$113,J120,$G$107:$G$113) -> 0 | H120: =E120+F120-G120 -> 78020 | I120: 입금통장 | J120: 하나704
B121: 하나은행 | C121: 332-910055-99304 | D121: MMDA | E121: 0 | F121: =SUMIF($H$47:$H$98,J121,$F$47:$F$98) -> 0 | G121: =SUMIF($H$47:$H$98,J121,$G$47:$G$98) -> 0 | H121: =E121+F121-G121 -> 0 | I121: SK네트웍스 | J121: 하나304
B122: 하나은행 | C122: 332-910056-00904 | D122: MMDA | E122: 0 | F122: =SUMIF($H$47:$H$98,J122,$F$47:$F$98) -> 0 | G122: =SUMIF($H$47:$H$98,J122,$G$47:$G$98) -> 0 | H122: =E122+F122-G122 -> 0 | I122: 하나비욘드파이낸스 | J122: 하나904
B123: 하나은행 | C123: 332-910056-75104 | D123: MMDA | E123: 0 | F123: =SUMIF($H$47:$H$98,J123,$F$47:$F$98) -> 0 | G123: =SUMIF($H$47:$H$98,J123,$G$47:$G$98) -> 0 | H123: =E123+F123-G123 -> 0 | I123: 교원넥스트 | J123: 하나104
B124: 기업은행 | C124: 137-114410-04-011 | D124: MMDA | E124: 23643752 | F124: =SUMIF($H$47:$H$98,J124,$F$47:$F$98) -> 0 | G124: =SUMIF($H$47:$H$98,J124,$G$47:$G$98) -> 0 | H124: =E124+F124-G124 -> 23643752 | I124: 운영자금 | J124: 기업011
B125: 수협은행 | C125: 1130-0059-0058 | D125: MMDA | E125: 0 | F125: =SUMIF($H$47:$H$98,J125,$F$47:$F$98) -> 0 | G125: =SUMIF($H$47:$H$98,J125,$G$47:$G$98) -> 0 | H125: =E125+F125-G125 -> 0 | I125: 교보문고 | J125: 수협058
B126: 농협은행 | C126: 301-0356-0848-51 | D126: 보통예금 | E126: 33952 | F126: =SUMIF($H$47:$H$98,J126,$F$47:$F$98) -> 0 | G126: =SUMIF($H$47:$H$98,J126,$G$47:$G$98) -> 0 | H126: =E126+F126-G126 -> 33952 | I126: 교보문고 | J126: 농협851
D127: 합계 | E127: =SUM(E118:E126) -> 321357313 | F127: =SUM(F118:F125) -> 0 | G127: =SUM(G118:G125) -> 0 | H127: =SUM(H118:H126) -> 321357313
B129: 2) 외화(USD) 수시입출 예금 | D129: ` | I129: (단위: 1U$)
B130: 은행 | C130: 계좌번호 | E130: 전일 잔액 | F130: 차변(입금) | G130: 대변(출금) | H130: 당일잔액 | I130: 비고
B131: 하나은행 | C131: 332-910013-40338 | D131: MMDA/USD | E131: 0 | F131: =SUMIF($H$100:$H$103,J131,$F$100:$F$103) -> 0 | G131: =SUMIF($H$100:$H$103,J131,$G$100:$G$103) -> 0 | H131: =E131+F131-G131 -> 0 | I131: 하나USD | J131: 하나USD
D132: 합계 | E132: =SUM(E131) -> 0 | F132: =SUM(F131) -> 0 | G132: =SUM(G131) -> 0 | H132: =SUM(H131) -> 0
B134: 3) 운용자금 | D134: ` | I134: (단위: 원)
B135: 은행 | C135: 계좌번호 | E135: 전일 잔액 | F135: 차변(입금) | G135: 대변(출금) | H135: 당일잔액 | I135: 비고
B136: 하나은행 | C136: 332-910293-62513 | D136: 단기채권(펀드)(2024.08.28 ~ ) | E136: 2100000000 | H136: =E136+F136-G136 -> 2100000000 | I136: 교원넥스트 | J136: 만기일 2027.08.28(36M) | M136: =H136-2057169001 -> 42830999
B137: 하나은행 | C137: 332-910304-53511 | D137: 정기예금(2025.06.20 ~ 2026.06.20)/2.52% | E137: 0 | H137: =E137+F137-G137 -> 0 | J137: 만기일 2026-06-22 / 해지일 2026-06-29
...

Sheet 0810
B1: 일일자금계획 | F1: 담 당 | G1: 차 장 | H1: 실 장 | I1: 담 당 임 원
B3: 주식회사 카탈리스터 | F3: 작성일자 | G3: 문서번호 | H3: 작성자 | I3: 보존연한
F4: 46244 | G4: 전략금융실-260810 | H4: 임정하 | I4: 3년
B6: 1. 일일자금수지 실적 | K6: 컴투버스 급여이체 담당자
A7: 계정과목 | B7: 통화구분 | C7: 거래처명 | D7: 내 역 | F7: 수입 | G7: 지출 | H7: 계좌 | I7: 비고 | K7: 하나은행 가산디지털지점 권은지 계장 02-852-1111(103)
B8: 1)원화
E40: 소계(￦) | F40: =SUM(F8:F39) -> 0 | G40: =SUM(G8:G39) -> 0
B41: 2) 외화(USD)
E43: 소계(U$) | F43: =SUM(F41:F42) -> 0 | G43: =SUM(G41:G42) -> 0
B45: 2. 일일자금수지 계획 | K45: ※ 실적, 계획 수지항목 = 외부로부터의 입출금내역만 기재.(보통예금, 자금대체 기재는 따로)
A46: 계정과목 | B46: 통화구분 | C46: 거래처명 | D46: 내 역 | F46: 수입 | G46: 지출 | H46: 계좌 | I46: 비고
A47: 원천세 | B47: 1) 원화 | C47: 금천세무서 | D47: 2026년 7월 근로소득세 원천징수 | G47: 3563860 | H47: 하나404 | I47: 홈텍스납부
A48: 원천세 | C48: 금천구청 | D48: 2026년 7월 근로소득주민세 원천징수 | G48: 356380 | H48: 하나404 | I48: 이지로납부
A49: 4대보험 | C49: 건강보험공단 | D49: 202607 4대보험-건강보험 | G49: 1678060 | H49: 하나404 | I49: 자동이체
A50: 4대보험 | C50: 국민연금공단 | D50: 202607 4대보험-연금보험 | G50: 1165240 | H50: 하나404 | I50: 자동이체
A51: 4대보험 | C51: 고용보험공단 | D51: 202607 4대보험-고용보험 | G51: =118010-250 -> 117760 | H51: 하나404 | I51: 자동이체
A52: 4대보험 | C52: 고용보험공단 | D52: 202607 4대보험-고용보험 | G52: =43180-250 -> 42930 | H52: 하나404 | I52: 자동이체
A53: 퇴직연금 | C53: 기업은행_가산디지털중앙 | D53: 임직원 퇴직연금_기업은행 | G53: 1466670 | H53: 기업011 | I53: 자동이체
A54: 지급수수료 | C54: 기업은행_가산디지털중앙 | D54: 2026년 퇴직연금 관리 수수료 납입의 건(기업은행) | G54: 476281 | H54: 하나404 | I54: 대량이체
A55: 퇴직연금 | C55: (주)한국투자증권 | D55: 임직원 퇴직연금_한국투자증권 | G55: 461810 | H55: 하나404
A56: 복리후생비 | C56: 삼성웰스토리(주)컴투스 | D56: 사내식당 임직원 식대 | G56: 216000 | H56: 하나404
A57: 기타지출 | C57: 주식회사 세포아소프트 | D57: 법인카드데이타 연동서비스 | G57: 110000 | H57: 하나404
A58: 기타지출 | C58: 아름다운세차 | D58: 임원 복리후생(정기세차) 비용 납부 | G58: 99000 | H58: 하나404
A59: 복리후생비 | C59: 최민준(주택자금대출) | D59: 주택자금대출 이자지원 | G59: 55956 | H59: 하나404
A60: 복리후생비 | C60: 카페 어썸 | D60: 사내카페 운영비용 | G60: 13700 | H60: 하나404
E102: 소계(￦) | F102: =SUM(F47:F101) -> 0 | G102: =SUM(G47:G101) -> 9823647
B103: 2) 외화(USD)
E107: 소계(U$) | F107: =SUM(F103:F106) -> 0 | G107: =SUM(G103:G106) -> 0
B108: 2-1. 자금대체
B109: 1) 원화 수시입출 예금 | D109: ` | I109: (단위: 원)
B110: 통화구분 | C110: 거래처명 | D110: 내 역 | F110: 수입 | G110: 지출 | H110: 계좌 | I110: 비고
E116: 소계(￦) | F116: =SUM(F111:F115) -> 0 | G116: =SUM(G111:G115) -> 0
B118: 3. 자금현황
B119: 1) 원화 수시입출 예금 | D119: ` | I119: (단위: 원)
B120: 은행 | C120: 계좌번호 | E120: 전일 잔액 | F120: 차변(입금) | G120: 대변(출금) | H120: 당일잔액 | I120: 비고
B121: 하나은행 | C121: 332-910058-20004 | D121: 보통예금 | E121: ='0731-1'!H118+SUMIF($H$8:$H$35,J121,$F$8:$F$35)-SUMIF($H$8:$H$35,J121,$G$8:$G$35) -> 115935 | F121: =SUMIF($H$47:$H$102,J121,$F$47:$F$102)+SUMIF($H$110:$H$116,J121,$F$110:$F$116) -> 0 | G121: =SUMIF($H$47:$H$102,J121,$G$47:$G$102)+SUMIF($H$110:$H$116,J121,$G$110:$G$116) -> 0 | H121: =E121+F121-G121 -> 115935 | I121: 연구개발과제 | J121: 하나004
B122: 하나은행 | C122: 332-910052-92404 | D122: MMDA | E122: ='0731-1'!H119+SUMIF($H$8:$H$35,J122,$F$8:$F$35)-SUMIF($H$8:$H$35,J122,$G$8:$G$35) -> 297485654 | F122: =SUMIF($H$47:$H$101,J122,$F$47:$F$101)+F116 -> 0 | G122: =SUMIF($H$47:$H$101,J122,$G$47:$G$101) -> 8356977 | H122: =E122+F122-G122 -> 289128677 | I122: 운영자금 | J122: 하나404
B123: 하나은행 | C123: 332-910055-98704 | D123: MMDA | E123: ='0731-1'!H120+SUMIF($H$8:$H$35,J123,$F$8:$F$35)-SUMIF($H$8:$H$35,J123,$G$8:$G$35)+SUMIF($H$110:$H$116,J123,$F$110:$F$116) -> 78020 | F123: =SUMIF($H$47:$H$101,J123,$F$47:$F$101)+SUMIF($H$110:$H$116,J123,$F$110:$F$116) -> 0 | G123: =SUMIF($H$47:$H$101,J123,$G$47:$G$101)+SUMIF($H$110:$H$116,J123,$G$110:$G$116) -> 0 | H123: =E123+F123-G123 -> 78020 | I123: 입금통장 | J123: 하나704
B124: 하나은행 | C124: 332-910055-99304 | D124: MMDA | E124: ='0731-1'!H121+SUMIF($H$8:$H$35,J124,$F$8:$F$35)-SUMIF($H$8:$H$35,J124,$G$8:$G$35) -> 0 | F124: =SUMIF($H$47:$H$101,J124,$F$47:$F$101) -> 0 | G124: =SUMIF($H$47:$H$101,J124,$G$47:$G$101) -> 0 | H124: =E124+F124-G124 -> 0 | I124: SK네트웍스 | J124: 하나304
B125: 하나은행 | C125: 332-910056-00904 | D125: MMDA | E125: ='0731-1'!H122+SUMIF($H$8:$H$35,J125,$F$8:$F$35)-SUMIF($H$8:$H$35,J125,$G$8:$G$35) -> 0 | F125: =SUMIF($H$47:$H$101,J125,$F$47:$F$101) -> 0 | G125: =SUMIF($H$47:$H$101,J125,$G$47:$G$101) -> 0 | H125: =E125+F125-G125 -> 0 | I125: 하나비욘드파이낸스 | J125: 하나904
...

Sheet 0820
B1: 일일자금계획 | F1: 담 당 | G1: 차 장 | H1: 실 장 | I1: 담 당 임 원
B3: 주식회사 카탈리스터 | F3: 작성일자 | G3: 문서번호 | H3: 작성자 | I3: 보존연한
F4: 46254 | G4: 전략금융실-260820 | H4: 임정하 | I4: 3년
B6: 1. 일일자금수지 실적 | K6: 컴투버스 급여이체 담당자
A7: 계정과목 | B7: 통화구분 | C7: 거래처명 | D7: 내 역 | F7: 수입 | G7: 지출 | H7: 계좌 | I7: 비고 | K7: 하나은행 가산디지털지점 권은지 계장 02-852-1111(103)
A8: 기타지출 | B8: 1)원화 | C8: 임직원 | D8: 260818직원비용-카탈리스터(8/18) | G8: 2656646 | H8: 하나404
A9: 기타지출 | C9: 삼성카드 | D9: 공용법인카드대금(8/18) | G9: 1289900 | H9: 하나404
A10: 기타지출 | C10: 삼성카드 | D10: 공용법인카드대금(8/18) | G10: 78166 | H10: 하나404
E40: 소계(￦) | F40: =SUM(F8:F39) -> 0 | G40: =SUM(G8:G39) -> 4024712
B41: 2) 외화(USD)
E43: 소계(U$) | F43: =SUM(F41:F42) -> 0 | G43: =SUM(G41:G42) -> 0
B45: 2. 일일자금수지 계획 | K45: ※ 실적, 계획 수지항목 = 외부로부터의 입출금내역만 기재.(보통예금, 자금대체 기재는 따로)
A46: 계정과목 | B46: 통화구분 | C46: 거래처명 | D46: 내 역 | F46: 수입 | G46: 지출 | H46: 계좌 | I46: 비고
A47: 지급임차료 | B47: 1) 원화 | C47: (주)컴투스 | D47: BYC 하이시티 B동 24층 월정임차료 | G47: 919248 | H47: 하나404 | I47: 대량이체
A48: 기타제세공과금 | C48: 금천구청 | D48: 2026년 주민세(사업소분) | G48: 250000 | H48: 하나404
A49: 경영지원용역비 | C49: (주)컴투스 | D49: 인사 용역료 지급 | G49: 43689 | H49: 하나404
A50: 전산유지비 | C50: ㈜닥터소프트 | D50: [확정] 자산관리 솔루션(Netrix) 유지보수 수수료 | G50: 825 | H50: 하나404
E102: 소계(￦) | F102: =SUM(F47:F101) -> 0 | G102: =SUM(G47:G101) -> 1213762
B103: 2) 외화(USD)
E107: 소계(U$) | F107: =SUM(F103:F106) -> 0 | G107: =SUM(G103:G106) -> 0
B108: 2-1. 자금대체
B109: 1) 원화 수시입출 예금 | D109: ` | I109: (단위: 원)
B110: 통화구분 | C110: 거래처명 | D110: 내 역 | F110: 수입 | G110: 지출 | H110: 계좌 | I110: 비고
E116: 소계(￦) | F116: =SUM(F111:F115) -> 0 | G116: =SUM(G111:G115) -> 0
B118: 3. 자금현황
B119: 1) 원화 수시입출 예금 | D119: ` | I119: (단위: 원)
B120: 은행 | C120: 계좌번호 | E120: 전일 잔액 | F120: 차변(입금) | G120: 대변(출금) | H120: 당일잔액 | I120: 비고
B121: 하나은행 | C121: 332-910058-20004 | D121: 보통예금 | E121: ='0810'!H121+SUMIF($H$8:$H$35,J121,$F$8:$F$35)-SUMIF($H$8:$H$35,J121,$G$8:$G$35) -> 115935 | F121: =SUMIF($H$47:$H$102,J121,$F$47:$F$102)+SUMIF($H$110:$H$116,J121,$F$110:$F$116) -> 0 | G121: =SUMIF($H$47:$H$102,J121,$G$47:$G$102)+SUMIF($H$110:$H$116,J121,$G$110:$G$116) -> 0 | H121: =E121+F121-G121 -> 115935 | I121: 연구개발과제 | J121: 하나004
B122: 하나은행 | C122: 332-910052-92404 | D122: MMDA | E122: ='0810'!H122+SUMIF($H$8:$H$35,J122,$F$8:$F$35)-SUMIF($H$8:$H$35,J122,$G$8:$G$35) -> 285103965 | F122: =SUMIF($H$47:$H$101,J122,$F$47:$F$101)+F116 -> 0 | G122: =SUMIF($H$47:$H$101,J122,$G$47:$G$101) -> 1213762 | H122: =E122+F122-G122 -> 283890203 | I122: 운영자금 | J122: 하나404
B123: 하나은행 | C123: 332-910055-98704 | D123: MMDA | E123: ='0810'!H123+SUMIF($H$8:$H$35,J123,$F$8:$F$35)-SUMIF($H$8:$H$35,J123,$G$8:$G$35)+SUMIF($H$110:$H$116,J123,$F$110:$F$116) -> 78020 | F123: =SUMIF($H$47:$H$101,J123,$F$47:$F$101)+SUMIF($H$110:$H$116,J123,$F$110:$F$116) -> 0 | G123: =SUMIF($H$47:$H$101,J123,$G$47:$G$101)+SUMIF($H$110:$H$116,J123,$G$110:$G$116) -> 0 | H123: =E123+F123-G123 -> 78020 | I123: 입금통장 | J123: 하나704
B124: 하나은행 | C124: 332-910055-99304 | D124: MMDA | E124: ='0810'!H124+SUMIF($H$8:$H$35,J124,$F$8:$F$35)-SUMIF($H$8:$H$35,J124,$G$8:$G$35) -> 0 | F124: =SUMIF($H$47:$H$101,J124,$F$47:$F$101) -> 0 | G124: =SUMIF($H$47:$H$101,J124,$G$47:$G$101) -> 0 | H124: =E124+F124-G124 -> 0 | I124: SK네트웍스 | J124: 하나304
B125: 하나은행 | C125: 332-910056-00904 | D125: MMDA | E125: ='0810'!H125+SUMIF($H$8:$H$35,J125,$F$8:$F$35)-SUMIF($H$8:$H$35,J125,$G$8:$G$35) -> 0 | F125: =SUMIF($H$47:$H$101,J125,$F$47:$F$101) -> 0 | G125: =SUMIF($H$47:$H$101,J125,$G$47:$G$101) -> 0 | H125: =E125+F125-G125 -> 0 | I125: 하나비욘드파이낸스 | J125: 하나904
B126: 하나은행 | C126: 332-910056-75104 | D126: MMDA | E126: ='0810'!H126+SUMIF($H$8:$H$35,J126,$F$8:$F$35)-SUMIF($H$8:$H$35,J126,$G$8:$G$35) -> 0 | F126: =SUMIF($H$47:$H$101,J126,$F$47:$F$101) -> 0 | G126: =SUMIF($H$47:$H$101,J126,$G$47:$G$101) -> 0 | H126: =E126+F126-G126 -> 0 | I126: 교원넥스트 | J126: 하나104
B127: 기업은행 | C127: 137-114410-04-011 | D127: MMDA | E127: ='0810'!H127+SUMIF($H$8:$H$35,J127,$F$8:$F$35)-SUMIF($H$8:$H$35,J127,$G$8:$G$35) -> 22177082 | F127: =SUMIF($H$47:$H$101,J127,$F$47:$F$101) -> 0 | G127: =SUMIF($H$47:$H$101,J127,$G$47:$G$101) -> 0 | H127: =E127+F127-G127 -> 22177082 | I127: 운영자금 | J127: 기업011
B128: 수협은행 | C128: 1130-0059-0058 | D128: MMDA | E128: ='0810'!H128+SUMIF($H$8:$H$35,J128,$F$8:$F$35)-SUMIF($H$8:$H$35,J128,$G$8:$G$35) -> 0 | F128: =SUMIF($H$47:$H$101,J128,$F$47:$F$101) -> 0 | G128: =SUMIF($H$47:$H$101,J128,$G$47:$G$101) -> 0 | H128: =E128+F128-G128 -> 0 | I128: 교보문고 | J128: 수협058
B129: 농협은행 | C129: 301-0356-0848-51 | D129: 보통예금 | E129: ='0810'!H129+SUMIF($H$8:$H$35,J129,$F$8:$F$35)-SUMIF($H$8:$H$35,J129,$G$8:$G$35) -> 33952 | F129: =SUMIF($H$47:$H$101,J129,$F$47:$F$101) -> 0 | G129: =SUMIF($H$47:$H$101,J129,$G$47:$G$101) -> 0 | H129: =E129+F129-G129 -> 33952 | I129: 교보문고 | J129: 농협851
D130: 합계 | E130: =SUM(E121:E129) -> 307508954 | F130: =SUM(F121:F128) -> 0 | G130: =SUM(G121:G128) -> 1213762 | H130: =SUM(H121:H129) -> 306295192
B132: 2) 외화(USD) 수시입출 예금 | D132: ` | I132: (단위: 1U$)
B133: 은행 | C133: 계좌번호 | E133: 전일 잔액 | F133: 차변(입금) | G133: 대변(출금) | H133: 당일잔액 | I133: 비고
B134: 하나은행 | C134: 332-910013-40338 | D134: MMDA/USD | E134: ='0810'!H134 -> 0 | F134: =SUMIF($H$103:$H$106,J134,$F$103:$F$106) -> 0 | G134: =SUMIF($H$103:$H$106,J134,$G$103:$G$106) -> 0 | H134: =E134+F134-G134 -> 0 | I134: 하나USD | J134: 하나USD
...

Sheet 0831
B1: 일일자금계획 | F1: 담 당 | G1: 차 장 | H1: 실 장 | I1: 담 당 임 원
B3: 주식회사 카탈리스터 | F3: 작성일자 | G3: 문서번호 | H3: 작성자 | I3: 보존연한
F4: 46265 | G4: 전략금융실-260831 | H4: 임정하 | I4: 3년
B6: 1. 일일자금수지 실적 | K6: 컴투버스 급여이체 담당자
A7: 계정과목 | B7: 통화구분 | C7: 거래처명 | D7: 내 역 | F7: 수입 | G7: 지출 | H7: 계좌 | I7: 비고 | K7: 하나은행 가산디지털지점 권은지 계장 02-852-1111(103)
A8: 급여 | B8: 1)원화 | C8: 임직원 | D8: 260825급여-카탈리스터(8/25) | G8: 14809777 | H8: 하나404
E40: 소계(￦) | F40: =SUM(F8:F39) -> 0 | G40: =SUM(G8:G39) -> 14809777
B41: 2) 외화(USD)
E43: 소계(U$) | F43: =SUM(F41:F42) -> 0 | G43: =SUM(G41:G42) -> 0
B45: 2. 일일자금수지 계획 | K45: ※ 실적, 계획 수지항목 = 외부로부터의 입출금내역만 기재.(보통예금, 자금대체 기재는 따로)
A46: 계정과목 | B46: 통화구분 | C46: 거래처명 | D46: 내 역 | F46: 수입 | G46: 지출 | H46: 계좌 | I46: 비고
A47: 전산유지비 | B47: 1) 원화 | C47: 베스핀글로벌 | D47: [확정] 구글 클라우드 플랫폼 EDP 이용료 | G47: 525415 | H47: 하나404 | I47: 대량이체
A48: 전산유지비 | C48: 텐센트코리아 | D48: [확정] 텐센트 클라우드 서비스 이용료 | G48: 323203 | H48: 하나404
A49: 기타지출 | C49: 주식회사 신도네트웍스 | D49: 사무실 복합기 소모품(토너) 구매 대금 | G49: 297000 | H49: 하나404
A50: 기타지출 | C50: 유플러스 | D50: 회사 대표번호 전화요금 지불의 건 | G50: 18700 | H50: 하나404
A51: 기타지출 | C51: LGU+통신전화 | D51: 통신비 | G51: 4380 | H51: 하나404 | I51: 자동이체
E102: 소계(￦) | F102: =SUM(F47:F101) -> 0 | G102: =SUM(G47:G101) -> 1168698
B103: 2) 외화(USD)
E107: 소계(U$) | F107: =SUM(F103:F106) -> 0 | G107: =SUM(G103:G106) -> 0
B108: 2-1. 자금대체
B109: 1) 원화 수시입출 예금 | D109: ` | I109: (단위: 원)
B110: 통화구분 | C110: 거래처명 | D110: 내 역 | F110: 수입 | G110: 지출 | H110: 계좌 | I110: 비고
E116: 소계(￦) | F116: =SUM(F111:F115) -> 0 | G116: =SUM(G111:G115) -> 0
B118: 3. 자금현황
B119: 1) 원화 수시입출 예금 | D119: ` | I119: (단위: 원)
B120: 은행 | C120: 계좌번호 | E120: 전일 잔액 | F120: 차변(입금) | G120: 대변(출금) | H120: 당일잔액 | I120: 비고
B121: 하나은행 | C121: 332-910058-20004 | D121: 보통예금 | E121: ='0820'!H121+SUMIF($H$8:$H$35,J121,$F$8:$F$35)-SUMIF($H$8:$H$35,J121,$G$8:$G$35) -> 115935 | F121: =SUMIF($H$47:$H$102,J121,$F$47:$F$102)+SUMIF($H$110:$H$116,J121,$F$110:$F$116) -> 0 | G121: =SUMIF($H$47:$H$102,J121,$G$47:$G$102)+SUMIF($H$110:$H$116,J121,$G$110:$G$116) -> 0 | H121: =E121+F121-G121 -> 115935 | I121: 연구개발과제 | J121: 하나004
B122: 하나은행 | C122: 332-910052-92404 | D122: MMDA | E122: ='0820'!H122+SUMIF($H$8:$H$35,J122,$F$8:$F$35)-SUMIF($H$8:$H$35,J122,$G$8:$G$35) -> 269080426 | F122: =SUMIF($H$47:$H$101,J122,$F$47:$F$101)+F116 -> 0 | G122: =SUMIF($H$47:$H$101,J122,$G$47:$G$101) -> 1168698 | H122: =E122+F122-G122 -> 267911728 | I122: 운영자금 | J122: 하나404
B123: 하나은행 | C123: 332-910055-98704 | D123: MMDA | E123: ='0820'!H123+SUMIF($H$8:$H$35,J123,$F$8:$F$35)-SUMIF($H$8:$H$35,J123,$G$8:$G$35)+SUMIF($H$110:$H$116,J123,$F$110:$F$116) -> 78020 | F123: =SUMIF($H$47:$H$101,J123,$F$47:$F$101)+SUMIF($H$110:$H$116,J123,$F$110:$F$116) -> 0 | G123: =SUMIF($H$47:$H$101,J123,$G$47:$G$101)+SUMIF($H$110:$H$116,J123,$G$110:$G$116) -> 0 | H123: =E123+F123-G123 -> 78020 | I123: 입금통장 | J123: 하나704
B124: 하나은행 | C124: 332-910055-99304 | D124: MMDA | E124: ='0820'!H124+SUMIF($H$8:$H$35,J124,$F$8:$F$35)-SUMIF($H$8:$H$35,J124,$G$8:$G$35) -> 0 | F124: =SUMIF($H$47:$H$101,J124,$F$47:$F$101) -> 0 | G124: =SUMIF($H$47:$H$101,J124,$G$47:$G$101) -> 0 | H124: =E124+F124-G124 -> 0 | I124: SK네트웍스 | J124: 하나304
B125: 하나은행 | C125: 332-910056-00904 | D125: MMDA | E125: ='0820'!H125+SUMIF($H$8:$H$35,J125,$F$8:$F$35)-SUMIF($H$8:$H$35,J125,$G$8:$G$35) -> 0 | F125: =SUMIF($H$47:$H$101,J125,$F$47:$F$101) -> 0 | G125: =SUMIF($H$47:$H$101,J125,$G$47:$G$101) -> 0 | H125: =E125+F125-G125 -> 0 | I125: 하나비욘드파이낸스 | J125: 하나904
B126: 하나은행 | C126: 332-910056-75104 | D126: MMDA | E126: ='0820'!H126+SUMIF($H$8:$H$35,J126,$F$8:$F$35)-SUMIF($H$8:$H$35,J126,$G$8:$G$35) -> 0 | F126: =SUMIF($H$47:$H$101,J126,$F$47:$F$101) -> 0 | G126: =SUMIF($H$47:$H$101,J126,$G$47:$G$101) -> 0 | H126: =E126+F126-G126 -> 0 | I126: 교원넥스트 | J126: 하나104
B127: 기업은행 | C127: 137-114410-04-011 | D127: MMDA | E127: ='0820'!H127+SUMIF($H$8:$H$35,J127,$F$8:$F$35)-SUMIF($H$8:$H$35,J127,$G$8:$G$35) -> 22177082 | F127: =SUMIF($H$47:$H$101,J127,$F$47:$F$101) -> 0 | G127: =SUMIF($H$47:$H$101,J127,$G$47:$G$101) -> 0 | H127: =E127+F127-G127 -> 22177082 | I127: 운영자금 | J127: 기업011
B128: 수협은행 | C128: 1130-0059-0058 | D128: MMDA | E128: ='0820'!H128+SUMIF($H$8:$H$35,J128,$F$8:$F$35)-SUMIF($H$8:$H$35,J128,$G$8:$G$35) -> 0 | F128: =SUMIF($H$47:$H$101,J128,$F$47:$F$101) -> 0 | G128: =SUMIF($H$47:$H$101,J128,$G$47:$G$101) -> 0 | H128: =E128+F128-G128 -> 0 | I128: 교보문고 | J128: 수협058
B129: 농협은행 | C129: 301-0356-0848-51 | D129: 보통예금 | E129: ='0820'!H129+SUMIF($H$8:$H$35,J129,$F$8:$F$35)-SUMIF($H$8:$H$35,J129,$G$8:$G$35) -> 33952 | F129: =SUMIF($H$47:$H$101,J129,$F$47:$F$101) -> 0 | G129: =SUMIF($H$47:$H$101,J129,$G$47:$G$101) -> 0 | H129: =E129+F129-G129 -> 33952 | I129: 교보문고 | J129: 농협851
D130: 합계 | E130: =SUM(E121:E129) -> 291485415 | F130: =SUM(F121:F128) -> 0 | G130: =SUM(G121:G128) -> 1168698 | H130: =SUM(H121:H129) -> 290316717
B132: 2) 외화(USD) 수시입출 예금 | D132: ` | I132: (단위: 1U$)
B133: 은행 | C133: 계좌번호 | E133: 전일 잔액 | F133: 차변(입금) | G133: 대변(출금) | H133: 당일잔액 | I133: 비고
B134: 하나은행 | C134: 332-910013-40338 | D134: MMDA/USD | E134: ='0820'!H134 -> 0 | F134: =SUMIF($H$103:$H$106,J134,$F$103:$F$106) -> 0 | G134: =SUMIF($H$103:$H$106,J134,$G$103:$G$106) -> 0 | H134: =E134+F134-G134 -> 0 | I134: 하나USD | J134: 하나USD
D135: 합계 | E135: =SUM(E134) -> 0 | F135: =SUM(F134) -> 0 | G135: =SUM(G134) -> 0 | H135: =SUM(H134) -> 0
...

Sheet 0831-1
B1: 일일자금계획 | F1: 담 당 | G1: 차 장 | H1: 실 장 | I1: 담 당 임 원
B3: 주식회사 카탈리스터 | F3: 작성일자 | G3: 문서번호 | H3: 작성자 | I3: 보존연한
F4: 2026-08-31(1) | G4: 전략금융실-260831(1) | H4: 임정하 | I4: 3년
B6: 1. 일일자금수지 실적 | K6: 컴투버스 급여이체 담당자
A7: 계정과목 | B7: 통화구분 | C7: 거래처명 | D7: 내 역 | F7: 수입 | G7: 지출 | H7: 계좌 | I7: 비고 | K7: 하나은행 가산디지털지점 권은지 계장 02-852-1111(103)
A8: 외상매출금 | B8: 1)원화 | C8: 컴투스플랫폼 | D8: 서버비 정산 | F8: 168355 | H8: 하나004
E40: 소계(￦) | F40: =SUM(F8:F39) -> 168355 | G40: =SUM(G8:G39) -> 0
B41: 2) 외화(USD)
E43: 소계(U$) | F43: =SUM(F41:F42) -> 0 | G43: =SUM(G41:G42) -> 0
B45: 2. 일일자금수지 계획 | K45: ※ 실적, 계획 수지항목 = 외부로부터의 입출금내역만 기재.(보통예금, 자금대체 기재는 따로)
A46: 계정과목 | B46: 통화구분 | C46: 거래처명 | D46: 내 역 | F46: 수입 | G46: 지출 | H46: 계좌 | I46: 비고
B47: 1) 원화
E102: 소계(￦) | F102: =SUM(F47:F101) -> 0 | G102: =SUM(G47:G101) -> 0
B103: 2) 외화(USD)
E107: 소계(U$) | F107: =SUM(F103:F106) -> 0 | G107: =SUM(G103:G106) -> 0
B108: 2-1. 자금대체
B109: 1) 원화 수시입출 예금 | D109: ` | I109: (단위: 원)
B110: 통화구분 | C110: 거래처명 | D110: 내 역 | F110: 수입 | G110: 지출 | H110: 계좌 | I110: 비고
E116: 소계(￦) | F116: =SUM(F111:F115) -> 0 | G116: =SUM(G111:G115) -> 0
B118: 3. 자금현황
B119: 1) 원화 수시입출 예금 | D119: ` | I119: (단위: 원)
B120: 은행 | C120: 계좌번호 | E120: 전일 잔액 | F120: 차변(입금) | G120: 대변(출금) | H120: 당일잔액 | I120: 비고
B121: 하나은행 | C121: 332-910058-20004 | D121: 보통예금 | E121: ='0831'!H121+SUMIF($H$8:$H$35,J121,$F$8:$F$35)-SUMIF($H$8:$H$35,J121,$G$8:$G$35) -> 284290 | F121: =SUMIF($H$47:$H$102,J121,$F$47:$F$102)+SUMIF($H$110:$H$116,J121,$F$110:$F$116) -> 0 | G121: =SUMIF($H$47:$H$102,J121,$G$47:$G$102)+SUMIF($H$110:$H$116,J121,$G$110:$G$116) -> 0 | H121: =E121+F121-G121 -> 284290 | I121: 연구개발과제 | J121: 하나004
B122: 하나은행 | C122: 332-910052-92404 | D122: MMDA | E122: ='0831'!H122+SUMIF($H$8:$H$35,J122,$F$8:$F$35)-SUMIF($H$8:$H$35,J122,$G$8:$G$35) -> 267911728 | F122: =SUMIF($H$47:$H$101,J122,$F$47:$F$101)+F116 -> 0 | G122: =SUMIF($H$47:$H$101,J122,$G$47:$G$101) -> 0 | H122: =E122+F122-G122 -> 267911728 | I122: 운영자금 | J122: 하나404
B123: 하나은행 | C123: 332-910055-98704 | D123: MMDA | E123: ='0831'!H123+SUMIF($H$8:$H$35,J123,$F$8:$F$35)-SUMIF($H$8:$H$35,J123,$G$8:$G$35)+SUMIF($H$110:$H$116,J123,$F$110:$F$116) -> 78020 | F123: =SUMIF($H$47:$H$101,J123,$F$47:$F$101)+SUMIF($H$110:$H$116,J123,$F$110:$F$116) -> 0 | G123: =SUMIF($H$47:$H$101,J123,$G$47:$G$101)+SUMIF($H$110:$H$116,J123,$G$110:$G$116) -> 0 | H123: =E123+F123-G123 -> 78020 | I123: 입금통장 | J123: 하나704
B124: 하나은행 | C124: 332-910055-99304 | D124: MMDA | E124: ='0831'!H124+SUMIF($H$8:$H$35,J124,$F$8:$F$35)-SUMIF($H$8:$H$35,J124,$G$8:$G$35) -> 0 | F124: =SUMIF($H$47:$H$101,J124,$F$47:$F$101) -> 0 | G124: =SUMIF($H$47:$H$101,J124,$G$47:$G$101) -> 0 | H124: =E124+F124-G124 -> 0 | I124: SK네트웍스 | J124: 하나304
B125: 하나은행 | C125: 332-910056-00904 | D125: MMDA | E125: ='0831'!H125+SUMIF($H$8:$H$35,J125,$F$8:$F$35)-SUMIF($H$8:$H$35,J125,$G$8:$G$35) -> 0 | F125: =SUMIF($H$47:$H$101,J125,$F$47:$F$101) -> 0 | G125: =SUMIF($H$47:$H$101,J125,$G$47:$G$101) -> 0 | H125: =E125+F125-G125 -> 0 | I125: 하나비욘드파이낸스 | J125: 하나904
B126: 하나은행 | C126: 332-910056-75104 | D126: MMDA | E126: ='0831'!H126+SUMIF($H$8:$H$35,J126,$F$8:$F$35)-SUMIF($H$8:$H$35,J126,$G$8:$G$35) -> 0 | F126: =SUMIF($H$47:$H$101,J126,$F$47:$F$101) -> 0 | G126: =SUMIF($H$47:$H$101,J126,$G$47:$G$101) -> 0 | H126: =E126+F126-G126 -> 0 | I126: 교원넥스트 | J126: 하나104
B127: 기업은행 | C127: 137-114410-04-011 | D127: MMDA | E127: ='0831'!H127+SUMIF($H$8:$H$35,J127,$F$8:$F$35)-SUMIF($H$8:$H$35,J127,$G$8:$G$35) -> 22177082 | F127: =SUMIF($H$47:$H$101,J127,$F$47:$F$101) -> 0 | G127: =SUMIF($H$47:$H$101,J127,$G$47:$G$101) -> 0 | H127: =E127+F127-G127 -> 22177082 | I127: 운영자금 | J127: 기업011
B128: 수협은행 | C128: 1130-0059-0058 | D128: MMDA | E128: ='0831'!H128+SUMIF($H$8:$H$35,J128,$F$8:$F$35)-SUMIF($H$8:$H$35,J128,$G$8:$G$35) -> 0 | F128: =SUMIF($H$47:$H$101,J128,$F$47:$F$101) -> 0 | G128: =SUMIF($H$47:$H$101,J128,$G$47:$G$101) -> 0 | H128: =E128+F128-G128 -> 0 | I128: 교보문고 | J128: 수협058
B129: 농협은행 | C129: 301-0356-0848-51 | D129: 보통예금 | E129: ='0831'!H129+SUMIF($H$8:$H$35,J129,$F$8:$F$35)-SUMIF($H$8:$H$35,J129,$G$8:$G$35) -> 33952 | F129: =SUMIF($H$47:$H$101,J129,$F$47:$F$101) -> 0 | G129: =SUMIF($H$47:$H$101,J129,$G$47:$G$101) -> 0 | H129: =E129+F129-G129 -> 33952 | I129: 교보문고 | J129: 농협851
D130: 합계 | E130: =SUM(E121:E129) -> 290485072 | F130: =SUM(F121:F128) -> 0 | G130: =SUM(G121:G128) -> 0 | H130: =SUM(H121:H129) -> 290485072
B132: 2) 외화(USD) 수시입출 예금 | D132: ` | I132: (단위: 1U$)
B133: 은행 | C133: 계좌번호 | E133: 전일 잔액 | F133: 차변(입금) | G133: 대변(출금) | H133: 당일잔액 | I133: 비고
B134: 하나은행 | C134: 332-910013-40338 | D134: MMDA/USD | E134: ='0831'!H134 -> 0 | F134: =SUMIF($H$103:$H$106,J134,$F$103:$F$106) -> 0 | G134: =SUMIF($H$103:$H$106,J134,$G$103:$G$106) -> 0 | H134: =E134+F134-G134 -> 0 | I134: 하나USD | J134: 하나USD
D135: 합계 | E135: =SUM(E134) -> 0 | F135: =SUM(F134) -> 0 | G135: =SUM(G134) -> 0 | H135: =SUM(H134) -> 0
B137: 3) 운용자금 | D137: ` | I137: (단위: 원)
B138: 은행 | C138: 계좌번호 | E138: 전일 잔액 | F138: 차변(입금) | G138: 대변(출금) | H138: 당일잔액 | I138: 비고
B139: 하나은행 | C139: 332-910293-62513 | D139: 단기채권(펀드)(2024.08.28 ~ ) | E139: ='0820'!H139 -> 2100000000 | H139: =E139+F139-G139 -> 2100000000 | I139: 교원넥스트 | J139: 만기일 2027.08.28(36M) | M139: =H139-2057169001 -> 42830999
B140: 하나은행 | C140: 332-910304-53511 | D140: 정기예금(2025.06.20 ~ 2026.06.20)/2.52% | E140: ='0820'!H140 -> 0 | H140: =E140+F140-G140 -> 0 | J140: 만기일 2026-06-22 / 해지일 2026-06-29
...
