Workbook
Name ___in7: [2]Disclaimer!#REF!
Name ___mds_first_cell___: [3]Condition!#REF!
Name ___mds_view_data___: [3]Condition!#REF!
Name __in7: [2]Disclaimer!#REF!
Name _in7: [2]Disclaimer!#REF!
Name aaa: #REF!
Name balance_04: #REF!
Name cap_act01: #REF!
Name cap_act01_cum: #REF!
Name cap_act02: #REF!
Name cap_act02_cum: #REF!
Name cap_bud01: #REF!
Name cap_bud01_cum: #REF!
Name cap_bud02: #REF!
Name cap_bud02_cum: #REF!
Name cap_US_act01: #REF!
Name cap_US_act01_cum: #REF!
Name cap_US_bud01: #REF!
Name cap_US_bud01_cum: #REF!
Name Depo: #REF!
Name detail_act01: #REF!
Name detail_bud01: #REF!
Name execsumm: #REF!
Name H00_CEO: #REF!
Name H10_재부장: #REF!
Name H11_기획: #REF!
Name H12_금융: #REF!
Name H13_회계: #REF!
Name H14_구매: #REF!
Name H20_운부장: #REF!
Name H21_Genco: #REF!
Name H22_영업: #REF!
Name H23_인사: #REF!
Name H3300_인사팀: #REF!
Name HM_공통: #REF!
Name hnh: #REF!
Name Impres_titres_MI: #REF!
Name inc_act: #REF!
Name inc_act_cum: #REF!
Name inc_act01: #REF!
Name inc_act01_cum: #REF!
Name inc_bud_cum: #REF!
Name inc_bud01: #REF!
Name inc_bud01_cum: #REF!
Name inc_bud01Feb: #REF!
Name inc_bud01Feb_cum: #REF!
Name inc_US_act01: #REF!
Name inc_US_act01_cum: #REF!
Name inc_US_bud01: #REF!
Name inc_US_bud01_cum: #REF!
Name MIX_P: #REF!
Name MIX_R: #REF!
Name mn: #REF!
Name month: #REF!
Name month_01: #REF!
Name oper_act: #REF!
Name oper_act_cum: #REF!
Name oper_bud_cum: #REF!
Name opr_act01: #REF!
Name opr_act01_cum: #REF!

Sheet 1-1
B3: 1. 8월 자금수지(Flow) | F3: =TEXT(ROUND(G14,1),"#,##0.0")&"백만"&" ("& "기초 " &TEXT(ROUND(G7,1),"#,###.0")&"백만"&" + 자금수지차 "&TEXT(ROUND(G12,1),"#,###.0")&"백만"&IF(G3=0,""," +"&" 자금조달 "&ROUND(G13,1)&"백만")&" = 기말 "&TEXT(ROUND(G14,1),"#,##0.0")&"백만)" -> 2,390.3백만 (기초 2,421.4백만 + 자금수지차 -31.0백만 = 기말 2,390.3백만)
I5: (단위 : 백만원)
E6: 구분 | F6: 7월(a) | G6: 8월(b) | H6: b - a | I6: 비고
E7: A. 기초잔고 | F7: ='3p'!I6+'2-1'!G6 -> 2462.4959 | G7: =F14 -> 2421.3573 | H7: =G7-F7 -> -41.138569 | I7: =_xlfn.CONCAT("○ 기초잔고: 유동자금 ",TEXT('3p'!L6,"#,##0.0"),"백만, ","운용자금 ",TEXT('2-1'!J6,"#,##0"),"백만") -> ○ 기초잔고: 유동자금 321.4백만, 운용자금 2,100백만
E8: B. 수입 | F8: ='3p'!I8 -> 0.134348 | G8: ='3p'!L8 -> 0.056328 | H8: =G8-F8 -> -0.07802
E10: C. 지출 | F10: ='3p'!I13 -> 41.272917 | G10: ='3p'!L13 -> 31.092138 | H10: =G10-F10 -> -10.180779 | I10: ● 7월 : 급여 15백만, 부가세 납부 3.7백만 등
I11: ○ 8월 : 급여 15백만 등
E12: D. 자금수지차 (=B-C) | F12: =F8-F10 -> -41.138569 | G12: =G8-G10 -> -31.03581 | H12: =G12-F12 -> 10.102759
E13: E. 자금조달 | F13: ='3p'!I45 -> 0 | G13: ='3p'!L45 -> 0 | H13: =G13-F13 -> 0
E14: G. 기말잔고 (=A+D+E) | F14: =F7+F12+F13 -> 2421.3573 | G14: =IF((G7+G12+G13)='2-2'!G16,(G7+G12+G13),'2-2'!G16) -> 2390.3215 | H14: =G14-F14 -> -31.03581 | I14: =_xlfn.CONCAT("○ 기말잔고: 유동자금 ",TEXT('3p'!L49,"#,##0.0"),"백만, ","운용자금 ",TEXT('2-1'!J12,"#,##0"),"백만") -> ○ 기말잔고: 유동자금 290.3백만, 운용자금 2,100백만
F16: ='3p'!I49+'2-1'!G12 -> 2421.3573 | G16: ='3p'!L49+'2-1'!J12 -> 2390.3215
F17: =F16=F14 -> TRUE | G17: =G16=G14 -> TRUE

Sheet 1-2
B2: 2. 유동자금 계획
G3: (단위 : 백만원, 천$)
C4: 구분 | D4: 8월 계획 | G4: 비고
D5: 원화 | E5: 외화($) | F5: 환산 계
C6: A. 기초 유동잔고 | D6: ='3p'!J6 -> 321.35731 | E6: ='3p'!K6/1000 -> 0 | F6: ='3p'!L6 -> 321.35731
C7: B. 수입 | D7: ='3p'!J8 -> 0.056328 | E7: ='3p'!K7/1000 -> 0 | F7: ='3p'!L8 -> 0.056328
C8: C. 지출 | D8: ='3p'!J13 -> 31.092138 | E8: ='3p'!K13/1000 -> 0 | F8: ='3p'!L13 -> 31.092138
C9: D. 자금수지차 (=B-C) | D9: =D7-D8 -> -31.03581 | E9: =E7-E8 -> 0 | F9: =F7-F8 -> -31.03581
C10: E. 자금과부족 (=A+D) | D10: =D6+D9 -> 290.3215 | E10: =E6+E9 -> 0 | F10: =F6+F9 -> 290.3215
C11: F. 운용자금 활용(해지) | D11: ='3p'!L40 -> 0 | E11: ='3p'!K45/1000 -> 0 | F11: =D11 -> 0
C12: G. 예치 전 기말 유동잔고(=E+F) | D12: =D10+D11 -> 290.3215 | E12: =E10+E11 -> 0 | F12: =F10+F11 -> 290.3215
C13: H. 예치 자금(=G-K) | D13: ='3p'!J41 -> 0 | E13: ='3p'!K41/1000 -> 0 | F13: ='3p'!L41 -> 0
C14: I. 기말 유동잔고 | D14: ='3p'!J49 -> 290.3215 | E14: ='3p'!K49/1000 -> 0 | F14: ='3p'!L49 -> 290.3215
C17: 구분 | D17: 6월 계획 | G17: 비고
D18: 원화 | E18: 외화($) | F18: 환산 계
C19: A. 기초잔고 (1월말 실적) | D19: =D6/100 -> 3.2135731 | E19: =E6/1000 -> 0 | F19: =F6/100 -> 3.2135731
D20: =#REF!/100 -> #REF! | E20: =#REF!/1000 -> #REF! | F20: =#REF!/100 -> #REF!
D21: =D7/100 -> 0.00056328 | E21: =E7/1000 -> 0 | F21: =F7/100 -> 0.00056328
D22: =#REF!/100 -> #REF! | E22: =#REF!/1000 -> #REF! | F22: =#REF!/100 -> #REF!
D23: =#REF!/100 -> #REF! | E23: =#REF!/1000 -> #REF! | F23: =#REF!/100 -> #REF!
D24: =D8/100 -> 0.31092138 | E24: =E8/1000 -> 0 | F24: =F8/100 -> 0.31092138
D26: =#REF!/100 -> #REF! | E26: =#REF!/1000 -> #REF! | F26: =#REF!/100 -> #REF!
C28: B. 자금수지차 (=a-b) | D28: =D9/100 -> -0.3103581 | E28: =E9/1000 -> 0 | F28: =F9/100 -> -0.3103581
C29: C. 기타 입출금(=c+d) | D29: =#REF!/100 -> #REF! | E29: =#REF!/1000 -> #REF! | F29: =#REF!/100 -> #REF!
D30: =D11/100 -> 0 | E30: =E11/100 -> 0 | F30: =F11/100 -> 0
C32: D. 자금과부족(=A+B+C) | D32: =D10/100 -> 2.903215 | E32: =E10/1000 -> 0 | F32: =F10/100 -> 2.903215
C33: E. 신규예치 가용금액 | D33: =D13/100 -> 0 | E33: =E13/1000 -> 0 | F33: =F13/100 -> 0
C34: F. 기말 잔고(6월말 계획=D-E) | D34: =D14/100 -> 2.903215 | E34: =E14/1000 -> 0 | F34: =F14/100 -> 2.903215
G36: `

Sheet 2-1
B2: 2. 운용자금 계획
K3: (단위 : 백만원, 천$)
C4: 구분 | E4: 7월 실적 | H4: 8월 계획 | K4: 비고
E5: 원화 | F5: 외화($) | G5: 환산 계 | H5: 원화 | I5: 외화($) | J5: 환산 계
C6: A. 기초자금 | E6: 2100 | F6: 0 | G6: =E6+F6*'7월데이터'!$I$1/1000 -> 2100 | H6: =E12 -> 2100 | I6: 0 | J6: =G12 -> 2100
C7: B. 해지(감소) | E7: ='3p'!G40 -> 0 | F7: ='3p'!H40 -> 0 | G7: ='3p'!I40 -> 0 | H7: ='3p'!J40 -> 0 | I7: ='3p'!K40 -> 0 | J7: ='3p'!L40 -> 0
C8: C. 금융기관예치 | E8: =IF(SUM(E9:E10)='3p'!G41,'3p'!G41,"불일치") -> 0 | F8: =IF(SUM(F9:F10)='3p'!H41,'3p'!H41,"불일치") -> 0 | G8: =IF(SUM(G9:G10)='3p'!I41,'3p'!I41,"불일치") -> 0 | H8: =IF(SUM(H9:H10)='3p'!J41,'3p'!J41,"불일치") -> 0 | I8: =IF(SUM(I9:I10)='3p'!K41,'3p'!K41,"불일치") -> 0 | J8: =IF(SUM(J9:J10)='3p'!L41,'3p'!L41,"불일치") -> 0
D9: 재예치 | E9: 0 | F9: 0 | G9: =E9+F9*'7월데이터'!$I$1/1000 -> 0 | H9: 0 | I9: 0 | J9: =H9+I9*'8월데이터'!$I$1/1000 -> 0
D10: 신규예치 | E10: 0 | F10: ='3p'!H41 -> 0 | G10: =E10+F10*'7월데이터'!$I$1/1000 -> 0 | H10: 0 | I10: ='3p'!K41 -> 0 | J10: =H10+I10*'8월데이터'!$I$1/1000 -> 0
C11: D. 운용자금 증감 (=C-B) | E11: =E8-E7 -> 0 | F11: =F8-F7 -> 0 | G11: =G8-G7 -> 0 | H11: =H8-H7 -> 0 | I11: =I8-I7 -> 0 | J11: =J8-J7 -> 0
C12: E. 기말자금 (=A+D) | E12: =E6+E11 -> 2100 | F12: =F6+F11 -> 0 | G12: =G6+G11 -> 2100 | H12: =H6+H11 -> 2100 | I12: =I6+I11 -> 0 | J12: =J6+J11 -> 2100
C14: ※ 외부 정합성 검증 (일일자금계획 파일 마지막 시트 대비)
C15: ① 유동자금 기말 — 집계값 (3p!I49) | G15: ='3p'!I49 -> 321.35731
C16: ② 유동자금 기말 — 실측값 (수시입출예금 당일잔액) | G16: 0
C18: ③ 운용자금 기말 — 집계값 (2-1!G12) | G18: =G12 -> 2100
C19: ④ 운용자금 기말 — 실측값 (운용자금 당일잔액) | G19: 0
C20: ⑤ 검증 결과 | G20: =IF(AND(G16=0,G19=0),"실측값 미입력",IF(AND(ABS(G15-G16)<0.0005,ABS(G18-G19)<0.0005),"일치","불일치 (유동 "&TEXT(G15-G16,"+#,##0.0;-#,##0.0;0")&" / 운용 "&TEXT(G18-G19,"+#,##0.0;-#,##0.0;0")&")")) -> 실측값 미입력

Sheet 2-2
B3: 4. 7월 말 자금(stock) : | F3: =TEXT(ROUND(G14,1),"#,##0.0")&"백만 (전월 대비 "&ROUND(H16,1)&"백만) = 유동자금 "&ROUND(G10,1)&"백만 ("&TEXT(ROUND(H10,1),"+#,##0.0;-#,##0.0;0")&"백만) + 운용자금 "&TEXT(ROUND(G13,1),"#,##0")&"백만 ("&TEXT(ROUND(H13,1),"+#,##0;-#,##0;0")&"백만)" -> 2,390.3백만 (전월 대비 -31백만) = 유동자금 290.3백만 (-31.0백만) + 운용자금 2,100백만 (0백만)
I4: (단위 : 백만원, 천$)
D5: 구분 | F5: 7월(a) | G5: 8월(b) | H5: b – a | I5: 비고
D6: A. 유동자금 | E6: 원화 | F6: ='3p'!G49 -> 321.35731 | G6: ='3p'!J49 -> 290.3215 | H6: =ROUND(G6-F6,2) -> -31.04 | I6: =K6 -> ① 원화 : -31.0백만 (= 수지차-31.0백만 + 운용자금 만기해지 +0백만) | K6: =_xlfn.CONCAT(" ① 원화 : ",TEXT(H6, "+#,##0.0;-#,##0.0;0"),"백만"," (= 수지차",TEXT('3p'!J7, "+#,##0.0;-#,##0.0;0"),"백만 ","+ 운용자금 만기해지 +",'3p'!J40,"백만)") -> ① 원화 : -31.0백만 (= 수지차-31.0백만 + 운용자금 만기해지 +0백만)
E7: 외화($) | F7: ='3p'!H49/1000 -> 0 | G7: ='3p'!K49 -> 0 | H7: =G7-F7 -> 0 | I7: ② 외화 : $ -천
I8: · 수입 : -
I9: · 지출 : -
D10: 환산 계 | F10: ='3p'!I49 -> 321.35731 | G10: ='3p'!L49 -> 290.3215 | H10: =ROUND(G10-F10,2) -> -31.04
D11: B. 운용자금 | E11: 원화 | F11: ='2-1'!E12 -> 2100 | G11: ='2-1'!H12 -> 2100 | H11: =G11-F11 -> 0
E12: 외화($) | F12: ='2-1'!F12 -> 0 | G12: ='2-1'!I12 -> 0 | H12: =G12-F12 -> 0
D13: 환산 계 | F13: ='2-1'!G12 -> 2100 | G13: ='2-1'!J12 -> 2100 | H13: =G13-F13 -> 0
D14: C. 기말자금 | E14: 원화 | F14: =F6+F11 -> 2421.3573 | G14: =G6+G11 -> 2390.3215 | H14: =G14-F14 -> -31.03581
D15: (A+B) | E15: 외화($) | F15: =F7+F12 -> 0 | G15: =G7+G12 -> 0 | H15: =G15-F15 -> 0
D16: 환산 계 | F16: =F10+F13 -> 2421.3573 | G16: =G10+G13 -> 2390.3215 | H16: =G16-F16 -> -31.03581
D17: 달러화 비율 | F17: =1-(F14/F16) -> 0 | G17: =1-(G14/G16) -> 0

Sheet 3p
A2: Ⅱ. 유동자금 계획 세부 내역 | I2: 784638
N3: (단위 : 백만원, 천$) | O3: 실적 환율(전월말 매매기준율) | P3: ='7월데이터'!$I$1 -> 1541.5
C4: 구분 | G4: 7월(실적) | J4: 8월(계획) | M4: b-a | N4: 비고 | O4: 계획 환율(전월말 매매기준율) | P4: ='8월데이터'!$I$1 -> 1541.5
G5: 원화 | H5: 외화($) | I5: 환산계(a) | J5: 원화 | K5: 외화($) | L5: 환산계(b)
C6: A. 기초유동잔고 | G6: 362.49588 | I6: =G6+H6*$P$3/1000 -> 362.49588 | J6: =G49 -> 321.35731 | K6: =H49 -> 0 | L6: =J6+K6*$P$4/1000 -> 321.35731 | M6: =L6-I6 -> -41.138569
C7: B. 수지차(=수입-지출) | G7: =G8-G13 -> -41.138569 | H7: =H8-H13 -> 0 | I7: =I8-I13 -> -41.138569 | J7: =J8-J13 -> -31.03581 | K7: =K8-K13 -> 0 | L7: =L8-L13 -> -31.03581 | M7: =-(L7-I7) -> -10.102759
D8: 수입 | G8: =SUM(G9:G12) -> 0.134348 | H8: =SUM(H9:H12) -> 0 | I8: =SUM(I9:I12) -> 0.134348 | J8: =SUM(J9:J12) -> 0.056328 | K8: =SUM(K9:K12) -> 0 | L8: =SUM(L9:L12) -> 0.056328 | M8: =SUM(M9:M12) -> -0.07802
E9: 매출 | G9: =SUMIFS('7월데이터'!$E:$E,'7월데이터'!$A:$A,"외상매출금",'7월데이터'!$D:$D,"KRW")/1000000 -> 0.056328 | H9: =SUMIFS('7월데이터'!$E:$E,'7월데이터'!$A:$A,"외상매출금",'7월데이터'!$D:$D,"USD")/1000 -> 0 | I9: =G9+H9*$P$3/1000 -> 0.056328 | J9: =SUMIFS('8월데이터'!$E:$E,'8월데이터'!$A:$A,"외상매출금",'8월데이터'!$D:$D,"KRW")/1000000 -> 0.056328 | K9: =SUMIFS('8월데이터'!$E:$E,'8월데이터'!$A:$A,"외상매출금",'8월데이터'!$D:$D,"USD")/1000 -> 0 | L9: =J9+K9*$P$4/1000 -> 0.056328 | M9: =L9-I9 -> 0
E10: 세금환급 | G10: =SUMIFS('7월데이터'!$E:$E,'7월데이터'!$A:$A,"세금환급",'7월데이터'!$D:$D,"KRW")/1000000 -> 0 | H10: =SUMIFS('7월데이터'!$E:$E,'7월데이터'!$A:$A,"세금환급",'7월데이터'!$D:$D,"USD")/1000 -> 0 | I10: =G10+H10*$P$3/1000 -> 0 | J10: =SUMIFS('8월데이터'!$E:$E,'8월데이터'!$A:$A,"세금환급",'8월데이터'!$D:$D,"KRW")/1000000 -> 0 | K10: =SUMIFS('8월데이터'!$E:$E,'8월데이터'!$A:$A,"세금환급",'8월데이터'!$D:$D,"USD")/1000 -> 0 | L10: =J10+K10*$P$4/1000 -> 0 | M10: =L10-I10 -> 0
E11: 이자수익 | G11: =SUMIFS('7월데이터'!$E:$E,'7월데이터'!$A:$A,"이자수익",'7월데이터'!$D:$D,"KRW")/1000000 -> 0 | H11: =SUMIFS('7월데이터'!$E:$E,'7월데이터'!$A:$A,"이자수익",'7월데이터'!$D:$D,"USD")/1000 -> 0 | I11: =G11+H11*$P$3/1000 -> 0 | J11: =SUMIFS('8월데이터'!$E:$E,'8월데이터'!$A:$A,"이자수익",'8월데이터'!$D:$D,"KRW")/1000000 -> 0 | K11: =SUMIFS('8월데이터'!$E:$E,'8월데이터'!$A:$A,"이자수익",'8월데이터'!$D:$D,"USD")/1000 -> 0 | L11: =J11+K11*$P$4/1000 -> 0 | M11: =L11-I11 -> 0
E12: 기타 | G12: =SUMIFS('7월데이터'!$E:$E,'7월데이터'!$A:$A,"기타",'7월데이터'!$D:$D,"KRW")/1000000+SUMIFS('7월데이터'!$E:$E,'7월데이터'!$A:$A,"수입임대료",'7월데이터'!$D:$D,"KRW")/1000000 -> 0.07802 | H12: =SUMIFS('7월데이터'!$E:$E,'7월데이터'!$A:$A,"기타",'7월데이터'!$D:$D,"USD")/1000+SUMIFS('7월데이터'!$E:$E,'7월데이터'!$A:$A,"수입임대료",'7월데이터'!$D:$D,"USD")/1000 -> 0 | I12: =G12+H12*$P$3/1000 -> 0.07802 | J12: =SUMIFS('8월데이터'!$E:$E,'8월데이터'!$A:$A,"기타",'8월데이터'!$D:$D,"KRW")/1000000+SUMIFS('8월데이터'!$E:$E,'8월데이터'!$A:$A,"수입임대료",'8월데이터'!$D:$D,"KRW")/1000000 -> 0 | K12: =SUMIFS('8월데이터'!$E:$E,'8월데이터'!$A:$A,"기타",'8월데이터'!$D:$D,"USD")/1000+SUMIFS('8월데이터'!$E:$E,'8월데이터'!$A:$A,"수입임대료",'8월데이터'!$D:$D,"USD")/1000 -> 0 | L12: =J12+K12*$P$4/1000 -> 0 | M12: =L12-I12 -> -0.07802
D13: 지출 | G13: =SUM(G14,G19,G20,G25:G28) -> 41.272917 | H13: =SUM(H14,H19,H20,H25:H28) -> 0 | I13: =SUM(I14,I19,I20,I25:I28) -> 41.272917 | J13: =SUM(J14,J19,J20,J25:J28) -> 31.092138 | K13: =SUM(K14,K19,K20,K25:K28) -> 0 | L13: =SUM(L14,L19,L20,L25:L28) -> 31.092138 | M13: =L13-I13 -> -10.180779
E14: 인건비 | G14: =SUM(G15:G18) -> 19.669627 | H14: =SUM(H15:H18) -> 0 | I14: =SUM(I15:I18) -> 19.669627 | J14: =SUM(J15:J18) -> 19.93247 | K14: =SUM(K15:K18) -> 0 | L14: =SUM(L15:L18) -> 19.93247 | M14: =L14-I14 -> 0.262843
F15: 급여 | G15: =SUMIFS('7월데이터'!$F:$F,'7월데이터'!$A:$A,"급여",'7월데이터'!$D:$D,"KRW")/1000000 -> 14.816477 | H15: =SUMIFS('7월데이터'!$F:$F,'7월데이터'!$A:$A,"급여",'7월데이터'!$D:$D,"USD")/1000 -> 0 | I15: =G15+H15*$P$3/1000 -> 14.816477 | J15: =SUMIFS('8월데이터'!$F:$F,'8월데이터'!$A:$A,"급여",'8월데이터'!$D:$D,"KRW")/1000000 -> 15 | K15: =SUMIFS('8월데이터'!$F:$F,'8월데이터'!$A:$A,"급여",'8월데이터'!$D:$D,"USD")/1000 -> 0 | L15: =J15+K15*$P$4/1000 -> 15 | M15: =L15-I15 -> 0.183523
F16: 상여 | G16: =SUMIFS('7월데이터'!$F:$F,'7월데이터'!$A:$A,"상여",'7월데이터'!$D:$D,"KRW")/1000000 -> 0 | H16: =SUMIFS('7월데이터'!$F:$F,'7월데이터'!$A:$A,"상여",'7월데이터'!$D:$D,"USD")/1000 -> 0 | I16: =G16+H16*$P$3/1000 -> 0 | J16: =SUMIFS('8월데이터'!$F:$F,'8월데이터'!$A:$A,"상여",'8월데이터'!$D:$D,"KRW")/1000000 -> 0 | K16: =SUMIFS('8월데이터'!$F:$F,'8월데이터'!$A:$A,"상여",'8월데이터'!$D:$D,"USD")/1000 -> 0 | L16: =J16+K16*$P$4/1000 -> 0 | M16: =L16-I16 -> 0
F17: 퇴직연금 | G17: =SUMIFS('7월데이터'!$F:$F,'7월데이터'!$A:$A,"퇴직연금",'7월데이터'!$D:$D,"KRW")/1000000 -> 1.92848 | H17: =SUMIFS('7월데이터'!$F:$F,'7월데이터'!$A:$A,"퇴직연금",'7월데이터'!$D:$D,"USD")/1000 -> 0 | I17: =G17+H17*$P$3/1000 -> 1.92848 | J17: =SUMIFS('8월데이터'!$F:$F,'8월데이터'!$A:$A,"퇴직연금",'8월데이터'!$D:$D,"KRW")/1000000 -> 1.92848 | K17: =SUMIFS('8월데이터'!$F:$F,'8월데이터'!$A:$A,"퇴직연금",'8월데이터'!$D:$D,"USD")/1000 -> 0 | L17: =J17+K17*$P$4/1000 -> 1.92848 | M17: =L17-I17 -> 0
F18: 4대보험 | G18: =SUMIFS('7월데이터'!$F:$F,'7월데이터'!$A:$A,"4대보험",'7월데이터'!$D:$D,"KRW")/1000000 -> 2.92467 | H18: =SUMIFS('7월데이터'!$F:$F,'7월데이터'!$A:$A,"4대보험",'7월데이터'!$D:$D,"USD")/1000 -> 0 | I18: =G18+H18*$P$3/1000 -> 2.92467 | J18: =SUMIFS('8월데이터'!$F:$F,'8월데이터'!$A:$A,"4대보험",'8월데이터'!$D:$D,"KRW")/1000000 -> 3.00399 | K18: =SUMIFS('8월데이터'!$F:$F,'8월데이터'!$A:$A,"4대보험",'8월데이터'!$D:$D,"USD")/1000 -> 0 | L18: =J18+K18*$P$4/1000 -> 3.00399 | M18: =L18-I18 -> 0.07932
E19: 마케팅비 | G19: =SUMIFS('7월데이터'!$F:$F,'7월데이터'!$A:$A,"마케팅비",'7월데이터'!$D:$D,"KRW")/1000000 -> 0 | H19: =SUMIFS('7월데이터'!$F:$F,'7월데이터'!$A:$A,"마케팅비",'7월데이터'!$D:$D,"USD")/1000 -> 0 | I19: =G19+H19*$P$3/1000 -> 0 | J19: =SUMIFS('8월데이터'!$F:$F,'8월데이터'!$A:$A,"마케팅비",'8월데이터'!$D:$D,"KRW")/1000000 -> 0 | K19: =SUMIFS('8월데이터'!$F:$F,'8월데이터'!$A:$A,"마케팅비",'8월데이터'!$D:$D,"USD")/1000 -> 0 | L19: =J19+K19*$P$4/1000 -> 0 | M19: =L19-I19 -> 0
E20: 제세공과금 | G20: =SUM(G21:G24) -> 7.57959 | H20: =SUM(H21:H24) -> 0 | I20: =SUM(I21:I24) -> 7.57959 | J20: =SUM(J21:J24) -> 4.17024 | K20: =SUM(K21:K24) -> 0 | L20: =SUM(L21:L24) -> 4.17024 | M20: =L20-I20 -> -3.40935
F21: 법인세 | G21: =SUMIFS('7월데이터'!$F:$F,'7월데이터'!$A:$A,"법인세",'7월데이터'!$D:$D,"KRW")/1000000 -> 0 | H21: =SUMIFS('7월데이터'!$F:$F,'7월데이터'!$A:$A,"법인세",'7월데이터'!$D:$D,"USD")/1000 -> 0 | I21: =G21+H21*$P$3/1000 -> 0 | J21: =SUMIFS('8월데이터'!$F:$F,'8월데이터'!$A:$A,"법인세",'8월데이터'!$D:$D,"KRW")/1000000 -> 0 | K21: =SUMIFS('8월데이터'!$F:$F,'8월데이터'!$A:$A,"법인세",'8월데이터'!$D:$D,"USD")/1000 -> 0 | L21: =J21+K21*$P$4/1000 -> 0 | M21: =L21-I21 -> 0
F22: 부가가치세 | G22: =SUMIFS('7월데이터'!$F:$F,'7월데이터'!$A:$A,"부가가치세",'7월데이터'!$D:$D,"KRW")/1000000 -> 3.65935 | H22: =SUMIFS('7월데이터'!$F:$F,'7월데이터'!$A:$A,"부가가치세",'7월데이터'!$D:$D,"USD")/1000 -> 0 | I22: =G22+H22*$P$3/1000 -> 3.65935 | J22: =SUMIFS('8월데이터'!$F:$F,'8월데이터'!$A:$A,"부가가치세",'8월데이터'!$D:$D,"KRW")/1000000 -> 0 | K22: =SUMIFS('8월데이터'!$F:$F,'8월데이터'!$A:$A,"부가가치세",'8월데이터'!$D:$D,"USD")/1000 -> 0 | L22: =J22+K22*$P$4/1000 -> 0 | M22: =L22-I22 -> -3.65935 | N22: ∙7월 : 1기 확정 부가가치세 납부 3.7백만
F23: 원천세 | G23: =SUMIFS('7월데이터'!$F:$F,'7월데이터'!$A:$A,"원천세",'7월데이터'!$D:$D,"KRW")/1000000 -> 3.92024 | H23: =SUMIFS('7월데이터'!$F:$F,'7월데이터'!$A:$A,"원천세",'7월데이터'!$D:$D,"USD")/1000 -> 0 | I23: =G23+H23*$P$3/1000 -> 3.92024 | J23: =SUMIFS('8월데이터'!$F:$F,'8월데이터'!$A:$A,"원천세",'8월데이터'!$D:$D,"KRW")/1000000 -> 3.92024 | K23: =SUMIFS('8월데이터'!$F:$F,'8월데이터'!$A:$A,"원천세",'8월데이터'!$D:$D,"USD")/1000 -> 0 | L23: =J23+K23*$P$4/1000 -> 3.92024 | M23: =L23-I23 -> 0
F24: 기타제세공과금 | G24: =SUMIFS('7월데이터'!$F:$F,'7월데이터'!$A:$A,"기타제세공과금",'7월데이터'!$D:$D,"KRW")/1000000 -> 0 | H24: =SUMIFS('7월데이터'!$F:$F,'7월데이터'!$A:$A,"기타제세공과금",'7월데이터'!$D:$D,"USD")/1000 -> 0 | I24: =G24+H24*$P$3/1000 -> 0 | J24: =SUMIFS('8월데이터'!$F:$F,'8월데이터'!$A:$A,"기타제세공과금",'8월데이터'!$D:$D,"KRW")/1000000 -> 0.25 | K24: =SUMIFS('8월데이터'!$F:$F,'8월데이터'!$A:$A,"기타제세공과금",'8월데이터'!$D:$D,"USD")/1000 -> 0 | L24: =J24+K24*$P$4/1000 -> 0.25 | M24: =L24-I24 -> 0.25
E25: 지급이자 | G25: =SUMIFS('7월데이터'!$F:$F,'7월데이터'!$A:$A,"지급이자",'7월데이터'!$D:$D,"KRW")/1000000 -> 0 | H25: =SUMIFS('7월데이터'!$F:$F,'7월데이터'!$A:$A,"지급이자",'7월데이터'!$D:$D,"USD")/1000 -> 0 | I25: =G25+H25*$P$3/1000 -> 0 | J25: =SUMIFS('8월데이터'!$F:$F,'8월데이터'!$A:$A,"지급이자",'8월데이터'!$D:$D,"KRW")/1000000 -> 0 | K25: =SUMIFS('8월데이터'!$F:$F,'8월데이터'!$A:$A,"지급이자",'8월데이터'!$D:$D,"USD")/1000 -> 0 | L25: =J25+K25*$P$4/1000 -> 0 | M25: =L25-I25 -> 0
E26: 자산매입 | G26: =SUMIFS('7월데이터'!$F:$F,'7월데이터'!$A:$A,"S/W",'7월데이터'!$D:$D,"KRW")/1000000+SUMIFS('7월데이터'!$F:$F,'7월데이터'!$A:$A,"H/W",'7월데이터'!$D:$D,"KRW")/1000000+SUMIFS('7월데이터'!$F:$F,'7월데이터'!$A:$A,"시설장치",'7월데이터'!$D:$D,"KRW")/1000000+SUMIFS('7월데이터'!$F:$F,'7월데이터'!$A:$A,"차량",'7월데이터'!$D:$D,"KRW")/1000000 -> 0 | H26: =SUMIFS('7월데이터'!$F:$F,'7월데이터'!$A:$A,"S/W",'7월데이터'!$D:$D,"USD")/1000+SUMIFS('7월데이터'!$F:$F,'7월데이터'!$A:$A,"H/W",'7월데이터'!$D:$D,"USD")/1000+SUMIFS('7월데이터'!$F:$F,'7월데이터'!$A:$A,"시설장치",'7월데이터'!$D:$D,"USD")/1000 -> 0 | I26: =G26+H26*$P$3/1000 -> 0 | J26: =SUMIFS('8월데이터'!$F:$F,'8월데이터'!$A:$A,"S/W",'8월데이터'!$D:$D,"KRW")/1000000+SUMIFS('8월데이터'!$F:$F,'8월데이터'!$A:$A,"H/W",'8월데이터'!$D:$D,"KRW")/1000000+SUMIFS('8월데이터'!$F:$F,'8월데이터'!$A:$A,"시설장치",'8월데이터'!$D:$D,"KRW")/1000000+SUMIFS('8월데이터'!$F:$F,'8월데이터'!$A:$A,"차량",'8월데이터'!$D:$D,"KRW")/1000000 -> 0 | K26: =SUMIFS('8월데이터'!$F:$F,'8월데이터'!$A:$A,"S/W",'8월데이터'!$D:$D,"USD")/1000+SUMIFS('8월데이터'!$F:$F,'8월데이터'!$A:$A,"H/W",'8월데이터'!$D:$D,"USD")/1000+SUMIFS('8월데이터'!$F:$F,'8월데이터'!$A:$A,"시설장치",'8월데이터'!$D:$D,"USD")/1000 -> 0 | L26: =J26+K26*$P$4/1000 -> 0 | M26: =L26-I26 -> 0
E27: 투자금 | G27: =SUMIFS('7월데이터'!$F:$F,'7월데이터'!$A:$A,"투자금",'7월데이터'!$D:$D,"KRW")/1000000 -> 0 | H27: =SUMIFS('7월데이터'!$F:$F,'7월데이터'!$A:$A,"투자금",'7월데이터'!$D:$D,"USD")/1000 -> 0 | I27: =G27+H27*$P$3/1000 -> 0 | J27: =SUMIFS('8월데이터'!$F:$F,'8월데이터'!$A:$A,"투자금",'8월데이터'!$D:$D,"KRW")/1000000 -> 0 | K27: =SUMIFS('8월데이터'!$F:$F,'8월데이터'!$A:$A,"투자금",'8월데이터'!$D:$D,"USD")/1000 -> 0 | L27: =J27+K27*$P$4/1000 -> 0 | M27: =L27-I27 -> 0
E28: 기타 | G28: =SUM(G29:G32) -> 14.0237 | H28: =SUM(H29:H32) -> 0 | I28: =SUM(I29:I32) -> 14.0237 | J28: =SUM(J29:J32) -> 6.989428 | K28: =SUM(K29:K32) -> 0 | L28: =SUM(L29:L32) -> 6.989428 | M28: =L28-I28 -> -7.034272
F29: 전산관련지출 | G29: =SUMIFS('7월데이터'!$F:$F,'7월데이터'!$A:$A,"전산관련지출",'7월데이터'!$D:$D,"KRW")/1000000 -> 0.685391 | H29: =SUMIFS('7월데이터'!$F:$F,'7월데이터'!$A:$A,"전산관련지출",'7월데이터'!$D:$D,"USD")/1000 -> 0 | I29: =G29+H29*$P$3/1000 -> 0.685391 | J29: =SUMIFS('8월데이터'!$F:$F,'8월데이터'!$A:$A,"전산관련지출",'8월데이터'!$D:$D,"KRW")/1000000 -> 0.685025 | K29: =SUMIFS('8월데이터'!$F:$F,'8월데이터'!$A:$A,"전산관련지출",'8월데이터'!$D:$D,"USD")/1000 -> 0 | L29: =J29+K29*$P$4/1000 -> 0.685025 | M29: =L29-I29 -> -0.000366
F30: 개발 외주용역비 | G30: =SUMIFS('7월데이터'!$F:$F,'7월데이터'!$A:$A,"외주용역비",'7월데이터'!$D:$D,"KRW")/1000000 -> 0 | H30: =SUMIFS('7월데이터'!$F:$F,'7월데이터'!$A:$A,"외주용역비",'7월데이터'!$D:$D,"USD")/1000 -> 0 | I30: =G30+H30*$P$3/1000 -> 0 | J30: =SUMIFS('8월데이터'!$F:$F,'8월데이터'!$A:$A,"외주용역비",'8월데이터'!$D:$D,"KRW")/1000000 -> 0 | K30: =SUMIFS('8월데이터'!$F:$F,'8월데이터'!$A:$A,"외주용역비",'8월데이터'!$D:$D,"USD")/1000 -> 0 | L30: =J30+K30*$P$4/1000 -> 0 | M30: =L30-I30 -> 0
F31: 경영, 업무지원, 운영용역비 | G31: =SUMIFS('7월데이터'!$F:$F,'7월데이터'!$A:$A,"경영지원용역비",'7월데이터'!$D:$D,"KRW")/1000000 -> 3.309631 | H31: =SUMIFS('7월데이터'!$F:$F,'7월데이터'!$A:$A,"경영지원용역비",'7월데이터'!$D:$D,"USD")/1000 -> 0 | I31: =G31+H31*$P$3/1000 -> 3.309631 | J31: =SUMIFS('8월데이터'!$F:$F,'8월데이터'!$A:$A,"경영지원용역비",'8월데이터'!$D:$D,"KRW")/1000000 -> 0.043689 | K31: =SUMIFS('8월데이터'!$F:$F,'8월데이터'!$A:$A,"경영지원용역비",'8월데이터'!$D:$D,"USD")/1000 -> 0 | L31: =J31+K31*$P$4/1000 -> 0.043689 | M31: =L31-I31 -> -3.265942 | N31: ∙7월 : 그룹사 공용비용 지급
F32: 기타 | G32: =SUMIFS('7월데이터'!$F:$F,'7월데이터'!$A:$A,"기타",'7월데이터'!$D:$D,"KRW")/1000000+SUMIFS('7월데이터'!$F:$F,'7월데이터'!$A:$A,"지급임차료",'7월데이터'!$D:$D,"KRW")/1000000+SUMIFS('7월데이터'!$F:$F,'7월데이터'!$A:$A,"지급수수료",'7월데이터'!$D:$D,"KRW")/1000000+SUMIFS('7월데이터'!$F:$F,'7월데이터'!$A:$A,"복리후생비",'7월데이터'!$D:$D,"KRW")/1000000+SUMIFS('7월데이터'!$F:$F,'7월데이터'!$A:$A,"식당운영비",'7월데이터'!$D:$D,"KRW")/1000000+SUMIFS('7월데이터'!$F:$F,'7월데이터'!$A:$A,"직원비용",'7월데이터'!$D:$D,"KRW")/1000000 -> 10.028678 | H32: =SUMIFS('7월데이터'!$F:$F,'7월데이터'!$A:$A,"기타",'7월데이터'!$D:$D,"USD")/1000+SUMIFS('7월데이터'!$F:$F,'7월데이터'!$A:$A,"지급임차료",'7월데이터'!$D:$D,"USD")/1000+SUMIFS('7월데이터'!$F:$F,'7월데이터'!$A:$A,"지급수수료",'7월데이터'!$D:$D,"USD")/1000+SUMIFS('7월데이터'!$F:$F,'7월데이터'!$A:$A,"복리후생비",'7월데이터'!$D:$D,"USD")/1000+SUMIFS('7월데이터'!$F:$F,'7월데이터'!$A:$A,"식당운영비",'7월데이터'!$D:$D,"USD")/1000+SUMIFS('7월데이터'!$F:$F,'7월데이터'!$A:$A,"직원비용",'7월데이터'!$D:$D,"USD")/1000 -> 0 | I32: =G32+H32*$P$3/1000 -> 10.028678 | J32: =SUMIFS('8월데이터'!$F:$F,'8월데이터'!$A:$A,"기타",'8월데이터'!$D:$D,"KRW")/1000000+SUMIFS('8월데이터'!$F:$F,'8월데이터'!$A:$A,"지급임차료",'8월데이터'!$D:$D,"KRW")/1000000+SUMIFS('8월데이터'!$F:$F,'8월데이터'!$A:$A,"지급수수료",'8월데이터'!$D:$D,"KRW")/1000000+SUMIFS('8월데이터'!$F:$F,'8월데이터'!$A:$A,"복리후생비",'8월데이터'!$D:$D,"KRW")/1000000+SUMIFS('8월데이터'!$F:$F,'8월데이터'!$A:$A,"식당운영비",'8월데이터'!$D:$D,"KRW")/1000000+SUMIFS('8월데이터'!$F:$F,'8월데이터'!$A:$A,"직원비용",'8월데이터'!$D:$D,"KRW")/1000000 -> 6.260714 | K32: =SUMIFS('8월데이터'!$F:$F,'8월데이터'!$A:$A,"기타",'8월데이터'!$D:$D,"USD")/1000+SUMIFS('8월데이터'!$F:$F,'8월데이터'!$A:$A,"지급임차료",'8월데이터'!$D:$D,"USD")/1000+SUMIFS('8월데이터'!$F:$F,'8월데이터'!$A:$A,"지급수수료",'8월데이터'!$D:$D,"USD")/1000+SUMIFS('8월데이터'!$F:$F,'8월데이터'!$A:$A,"복리후생비",'8월데이터'!$D:$D,"USD")/1000+SUMIFS('8월데이터'!$F:$F,'8월데이터'!$A:$A,"식당운영비",'8월데이터'!$D:$D,"USD")/1000+SUMIFS('8월데이터'!$F:$F,'8월데이터'!$A:$A,"직원비용",'8월데이터'!$D:$D,"USD")/1000 -> 0 | L32: =J32+K32*$P$4/1000 -> 6.260714 | M32: =L32-I32 -> -3.767964
F33: 복리후생비 | G33: =SUMIFS('7월데이터'!$F:$F,'7월데이터'!$A:$A,"복리후생비",'7월데이터'!$D:$D,"KRW")/1000000 -> 0.156247 | H33: =SUMIFS('7월데이터'!$F:$F,'7월데이터'!$A:$A,"복리후생비",'7월데이터'!$D:$D,"USD")/1000 -> 0 | I33: =G33+H33*$P$3/1000 -> 0.156247 | J33: =SUMIFS('8월데이터'!$F:$F,'8월데이터'!$A:$A,"복리후생비",'8월데이터'!$D:$D,"KRW")/1000000 -> 0.154956 | K33: =SUMIFS('8월데이터'!$F:$F,'8월데이터'!$A:$A,"복리후생비",'8월데이터'!$D:$D,"USD")/1000 -> 0 | L33: =J33+K33*$P$4/1000 -> 0.154956 | M33: =L33-I33 -> -0.001291
F34: 식당, 카페 등 운영비 | G34: =SUMIFS('7월데이터'!$F:$F,'7월데이터'!$A:$A,"식당운영비",'7월데이터'!$D:$D,"KRW")/1000000 -> 0 | H34: =SUMIFS('7월데이터'!$F:$F,'7월데이터'!$A:$A,"식당운영비",'7월데이터'!$D:$D,"USD")/1000 -> 0 | I34: =G34+H34*$P$3/1000 -> 0 | J34: =SUMIFS('8월데이터'!$F:$F,'8월데이터'!$A:$A,"식당운영비",'8월데이터'!$D:$D,"KRW")/1000000 -> 0.2297 | K34: =SUMIFS('8월데이터'!$F:$F,'8월데이터'!$A:$A,"식당운영비",'8월데이터'!$D:$D,"USD")/1000 -> 0 | L34: =J34+K34*$P$4/1000 -> 0.2297 | M34: =L34-I34 -> 0.2297
F35: 직원비용, 복지포인트 | G35: =SUMIFS('7월데이터'!$F:$F,'7월데이터'!$A:$A,"직원비용",'7월데이터'!$D:$D,"KRW")/1000000 -> 8.717161 | H35: =SUMIFS('7월데이터'!$F:$F,'7월데이터'!$A:$A,"직원비용",'7월데이터'!$D:$D,"USD")/1000 -> 0 | I35: =G35+H35*$P$3/1000 -> 8.717161 | J35: =SUMIFS('8월데이터'!$F:$F,'8월데이터'!$A:$A,"직원비용",'8월데이터'!$D:$D,"KRW")/1000000 -> 4.028322 | K35: =SUMIFS('8월데이터'!$F:$F,'8월데이터'!$A:$A,"직원비용",'8월데이터'!$D:$D,"USD")/1000 -> 0 | L35: =J35+K35*$P$4/1000 -> 4.028322 | M35: =L35-I35 -> -4.688839
F36: 임차료, 관리비 | G36: =SUMIFS('7월데이터'!$F:$F,'7월데이터'!$A:$A,"지급임차료",'7월데이터'!$D:$D,"KRW")/1000000 -> 0.919248 | H36: =SUMIFS('7월데이터'!$F:$F,'7월데이터'!$A:$A,"지급임차료",'7월데이터'!$D:$D,"USD")/1000 -> 0 | I36: =G36+H36*$P$3/1000 -> 0.919248 | J36: =SUMIFS('8월데이터'!$F:$F,'8월데이터'!$A:$A,"지급임차료",'8월데이터'!$D:$D,"KRW")/1000000 -> 0.919248 | K36: =SUMIFS('8월데이터'!$F:$F,'8월데이터'!$A:$A,"지급임차료",'8월데이터'!$D:$D,"USD")/1000 -> 0 | L36: =J36+K36*$P$4/1000 -> 0.919248 | M36: =L36-I36 -> 0
F37: 지급수수료 | G37: =SUMIFS('7월데이터'!$F:$F,'7월데이터'!$A:$A,"지급수수료",'7월데이터'!$D:$D,"KRW")/1000000 -> 0 | H37: =SUMIFS('7월데이터'!$F:$F,'7월데이터'!$A:$A,"지급수수료",'7월데이터'!$D:$D,"USD")/1000 -> 0 | I37: =G37+H37*$P$3/1000 -> 0 | J37: =SUMIFS('8월데이터'!$F:$F,'8월데이터'!$A:$A,"지급수수료",'8월데이터'!$D:$D,"KRW")/1000000 -> 0.476281 | K37: =SUMIFS('8월데이터'!$F:$F,'8월데이터'!$A:$A,"지급수수료",'8월데이터'!$D:$D,"USD")/1000 -> 0 | L37: =J37+K37*$P$4/1000 -> 0.476281 | M37: =L37-I37 -> 0.476281
F38: 통신비등 | G38: =G32-SUM(G33:G37) -> 0.236022 | H38: =H32-SUM(H33:H37) -> 0 | I38: =G38+H38*$P$3/1000 -> 0.236022 | J38: =J32-SUM(J33:J37) -> 0.452207 | K38: =K32-SUM(K33:K37) -> 0 | L38: =J38+K38*$P$4/1000 -> 0.452207 | M38: =L38-I38 -> 0.216185
C39: C. 운용자금 입지출(=해지-예치) | G39: =G40-G41 -> 0 | H39: =H40-H41 -> 0 | I39: =I40-I41 -> 0 | J39: =J40-J41 -> 0 | K39: =K40-K41 -> 0 | L39: =L40-L41 -> 0 | M39: =L39-I39 -> 0
D40: 해지(입금) | G40: =SUMIFS('7월데이터'!$E:$E,'7월데이터'!$A:$A,"금융상품",'7월데이터'!$D:$D,"KRW")/1000000 -> 0 | H40: =SUMIFS('7월데이터'!$E:$E,'7월데이터'!$A:$A,"금융상품",'7월데이터'!$D:$D,"USD")/1000 -> 0 | I40: =G40+H40*$P$3/1000 -> 0 | J40: =SUMIFS('8월데이터'!$E:$E,'8월데이터'!$A:$A,"금융상품",'8월데이터'!$D:$D,"KRW")/1000000 -> 0 | K40: =SUMIFS('8월데이터'!$E:$E,'8월데이터'!$A:$A,"금융상품",'8월데이터'!$D:$D,"USD")/1000 -> 0 | L40: =J40+K40*$P$4/1000 -> 0 | M40: =L40-I40 -> 0
D41: 예치(지출) | G41: =SUMIFS('7월데이터'!$F:$F,'7월데이터'!$A:$A,"금융상품",'7월데이터'!$D:$D,"KRW")/1000000 -> 0 | H41: =SUMIFS('7월데이터'!$F:$F,'7월데이터'!$A:$A,"금융상품",'7월데이터'!$D:$D,"USD")/1000 -> 0 | I41: =G41+H41*$P$3/1000 -> 0 | J41: =SUMIFS('8월데이터'!$F:$F,'8월데이터'!$A:$A,"금융상품",'8월데이터'!$D:$D,"KRW")/1000000 -> 0 | K41: =SUMIFS('8월데이터'!$F:$F,'8월데이터'!$A:$A,"금융상품",'8월데이터'!$D:$D,"USD")/1000 -> 0 | L41: =J41+K41*$P$4/1000 -> 0 | M41: =L41-I41 -> 0
...

Sheet 연간
A2: Ⅱ. 연간 자금수지 | O2: 771398
AV3: (단위 : 백만원, 천$) | AW3: 12
C4: 구분 | G4: 1월 | J4: 2월 | M4: 3월 | P4: 4월 | S4: 5월 | V4: 6월 | Y4: 7월 | AB4: 8월 | AE4: 9월 | AH4: 10월 | AK4: 11월 | AN4: 12월 | AQ4: 합계 | AT4: 평균
G5: 원화 | H5: 외화($) | I5: 환산계(a) | J5: 원화 | K5: 외화($) | L5: 환산계(b) | M5: 원화 | N5: 외화($) | O5: 환산계(a) | P5: 원화 | Q5: 외화($) | R5: 환산계(b) | S5: 원화 | T5: 외화($) | U5: 환산계(b) | V5: 원화 | W5: 외화($) | X5: 환산계(b) | Y5: 원화 | Z5: 외화($) | AA5: 환산계(b) | AB5: 원화 | AC5: 외화($) | AD5: 환산계(b) | AE5: 원화 | AF5: 외화($) | AG5: 환산계(b) | AH5: 원화 | AI5: 외화($) | AJ5: 환산계(b) | AK5: 원화 | AL5: 외화($) | AM5: 환산계(b) | AN5: 원화 | AO5: 외화($) | AP5: 환산계(b) | AQ5: 원화 | AR5: 외화($) | AS5: 환산계(b) | AT5: 원화 | AU5: 외화($) | AV5: 환산계(b)
C6: A. 기초잔고 | G6: 3607.0898 | H6: 0 | I6: =G6+H6*$R$52/1000 -> 3607.0898 | J6: =G50 -> 3561.0752 | K6: =H50 -> 0 | L6: =J6+K6*$R$52/1000 -> 3561.0752 | M6: =J50 -> 3497.4781 | N6: 0 | O6: =M6+N6*$R$52/1000 -> 3497.4781 | P6: =M50 -> 2471.3553 | Q6: 0 | R6: =P6+Q6*$R$52/1000 -> 2471.3553 | S6: =P50 -> 2470.299 | T6: =Q50 -> 0 | U6: =S6+T6*U52/1000 -> 2470.299 | V6: =S50 -> 2488.7483 | W6: =Q50 -> 0 | X6: =V6+W6*X52/1000 -> 2488.7483 | Y6: =V50 -> 2462.4869 | Z6: =T50 -> 0 | AA6: =Y6+Z6*AA52/1000 -> 2462.4869 | AB6: =Y50 -> 2421.3483 | AC6: =T50 -> 0 | AD6: =AB6+AC6*AD52/1000 -> 2421.3483 | AE6: =AB50 -> 2390.3125 | AF6: =T50 -> 0 | AG6: =AE6+AF6*AG52/1000 -> 2390.3125 | AH6: =AE50 -> 2390.3125 | AI6: =T50 -> 0 | AJ6: =AH6+AI6*AJ52/1000 -> 2390.3125 | AK6: =AH50 -> 2390.3125 | AL6: =T50 -> 0 | AM6: =AK6+AL6*AM52/1000 -> 2390.3125 | AN6: =AK50 -> 2390.3125 | AO6: =W50 -> 0 | AP6: =AN6+AO6*AP52/1000 -> 2390.3125 | AQ6: =G6 -> 3607.0898 | AR6: =Z50 -> 0 | AS6: =AQ6+AR6*AS52/1000 -> 3607.0898 | AU6: =AC50 -> 0 | AV6: =AT6+AU6*AV52/1000 -> 0
C7: B. 수지차(=수입-지출) | G7: =G8-G13 -> -46.01464 | H7: =H8-H13 -> 0 | I7: =I8-I13 -> -46.01464 | J7: =J8-J13 -> -63.59707 | K7: =K8-K13 -> 0 | L7: =L8-L13 -> -63.59707 | M7: =M8-M13 -> -1026.1228 | N7: =N8-N13 -> 0 | ... AV7: =AV8-AV13 -> -83.927954
D8: 수입 | G8: =SUM(G9:G12) -> 16.726369 | H8: =SUM(H9:H12) -> 0 | I8: =SUM(I9:I12) -> 16.726369 | J8: =SUM(J9:J12) -> 1.412739 | K8: =SUM(K9:K12) -> 0 | L8: =SUM(L9:L12) -> 1.412739 | M8: =SUM(M9:M12) -> 0.632712 | N8: =SUM(N9:N12) -> 0 | ... AV8: =SUM(AV9:AV12) -> 0
E9: 매출 | G9: 0 | H9: 0 | I9: =G9+H9*$R$52/1000 -> 0 | J9: 0 | K9: 0 | L9: =J9+K9*$R$52/1000 -> 0 | M9: 0.09209 | N9: 0 | O9: =M9+N9*$R$52/1000 -> 0.09209 | P9: 0 | Q9: 0 | R9: =P9+Q9*$R$52/1000 -> 0 | S9: 0 | T9: 0 | U9: =S9+T9*U52/1000 -> 0 | V9: 0.05181 | W9: 0 | X9: =V9+W9*X52/1000 -> 0.05181 | Y9: 0.056328 | Z9: 0 | AA9: =Y9+Z9*AA52/1000 -> 0.056328 | AB9: 0.056328 | AC9: 0 | AD9: =AB9+AC9*AD52/1000 -> 0.056328 | AG9: =AE9+AF9*AG52/1000 -> 0 | AJ9: =AH9+AI9*AJ52/1000 -> 0 | AM9: =AK9+AL9*AM52/1000 -> 0 | AP9: =AN9+AO9*AP52/1000 -> 0 | AS9: =AQ9+AR9*AS52/1000 -> 0 | AT9: =AQ9/$AW$3 -> 0 | AU9: =SUM(K9,N9,Q9,T9,W9,Z9,AC9,AF9,AI9,AL9,AO9,AR9) -> 0 | AV9: =AT9+AU9*AV52/1000 -> 0
E10: 세금 환급 | G10: 0 | H10: 0 | I10: =G10+H10*$R$52/1000 -> 0 | J10: 1.27178 | K10: 0 | L10: =J10+K10*$R$52/1000 -> 1.27178 | M10: 0 | N10: 0 | O10: =M10+N10*$R$52/1000 -> 0 | P10: 14.97952 | Q10: 0 | R10: =P10+Q10*$R$52/1000 -> 14.97952 | S10: 1.49789 | T10: 0 | U10: =S10+T10*U52/1000 -> 1.49789 | V10: 0 | W10: 0 | X10: =V10+W10*X52/1000 -> 0 | Y10: 0 | Z10: 0 | AA10: =Y10+Z10*AA52/1000 -> 0 | AB10: 0 | AC10: 0 | AD10: =AB10+AC10*AD52/1000 -> 0 | AG10: =AE10+AF10*AG54/1000 -> 0 | AJ10: =AH10+AI10*AJ52/1000 -> 0 | AM10: =AK10+AL10*AM52/1000 -> 0 | AP10: =AN10+AO10*AP52/1000 -> 0 | AS10: =AQ10+AR10*AS52/1000 -> 0 | AT10: =AQ10/$AW$3 -> 0 | AU10: =SUM(K10,N10,Q10,T10,W10,Z10,AC10,AF10,AI10,AL10,AO10,AR10) -> 0 | AV10: =AT10+AU10*AV52/1000 -> 0
E11: 이자수익 | G11: 14.92319 | H11: 0 | I11: =G11+H11*$R$52/1000 -> 14.92319 | J11: 0 | K11: 0 | L11: =J11+K11*$R$52/1000 -> 0 | M11: 0.540622 | N11: 0 | O11: =M11+N11*$R$52/1000 -> 0.540622 | P11: 0 | Q11: 0 | R11: =P11+Q11*$R$52/1000 -> 0 | S11: 0 | T11: 0 | U11: =S11+T11*$U52/1000 -> 0 | V11: 6.483723 | W11: 0 | X11: =V11+W11*$U52/1000 -> 6.483723 | Y11: 0 | Z11: 0 | AA11: =Y11+Z11*$U52/1000 -> 0 | AB11: 0 | AC11: 0 | AD11: =AB11+AC11*$U52/1000 -> 0 | AG11: =AE11+AF11*$U52/1000 -> 0 | AJ11: =AH11+AI11*$U52/1000 -> 0 | AM11: =AK11+AL11*$U52/1000 -> 0 | AP11: =AN11+AO11*$U52/1000 -> 0 | AS11: =AQ11+AR11*$U52/1000 -> 0 | AT11: =AQ11/$AW$3 -> 0 | AU11: =SUM(K11,N11,Q11,T11,W11,Z11,AC11,AF11,AI11,AL11,AO11,AR11) -> 0 | AV11: =AT11+AU11*$U52/1000 -> 0
E12: 기타 | G12: 1.803179 | H12: 0 | I12: =G12+H12*$R$52/1000 -> 1.803179 | J12: 0.140959 | K12: 0 | L12: =J12+K12*$R$52/1000 -> 0.140959 | M12: 0 | N12: 0 | O12: =M12+N12*$R$52/1000 -> 0 | P12: =15.37848+0.130058 -> 15.508538 | Q12: 0 | R12: =P12+Q12*$R$52/1000 -> 15.508538 | S12: 51.185792 | T12: 0 | U12: =S12+T12*U52/1000 -> 51.185792 | V12: 0 | W12: 0 | X12: =V12+W12*X52/1000 -> 0 | Y12: 0.07802 | Z12: 0 | AA12: =Y12+Z12*AA52/1000 -> 0.07802 | AB12: 0 | AC12: 0 | AD12: =AB12+AC12*AD52/1000 -> 0 | AG12: =AE12+AF12*AG52/1000 -> 0 | AJ12: =AH12+AI12*AJ52/1000 -> 0 | AM12: =AK12+AL12*AM52/1000 -> 0 | AP12: =AN12+AO12*AP52/1000 -> 0 | AS12: =AQ12+AR12*AS52/1000 -> 0 | AT12: =AQ12/$AW$3 -> 0 | AU12: =SUM(K12,N12,Q12,T12,W12,Z12,AC12,AF12,AI12,AL12,AO12,AR12) -> 0 | AV12: =AT12+AU12*AV52/1000 -> 0
D13: 지출 | G13: =SUM(G14,G19,G20,G25:G28) -> 62.741009 | H13: =SUM(H14,H19,H20,H25:H28) -> 0 | I13: =SUM(I14,I19,I20,I25:I28) -> 62.741009 | J13: =SUM(J14,J19,J20,J25:J28) -> 65.009809 | K13: =SUM(K14,K19,K20,K25:K28) -> 0 | L13: =SUM(L14,L19,L20,L25:L28) -> 65.009809 | M13: =SUM(M14,M19,M20,M25:M28) -> 1026.7555 | N13: =SUM(N14,N19,N20,N25:N28) -> 0 | ... AV13: =SUM(AV14,AV19,AV20,AV25:AV28) -> 83.927954
E14: 인건비 | G14: =SUM(G15:G18) -> 43.63493 | H14: =SUM(H15:H18) -> 0 | I14: =SUM(I15:I18) -> 43.63493 | J14: =SUM(J15:J18) -> 38.99243 | K14: =SUM(K15:K18) -> 0 | L14: =SUM(L15:L18) -> 38.99243 | M14: =SUM(M15:M18) -> 20.246437 | N14: =SUM(N15:N18) -> 0 | ... AV14: =SUM(AV15:AV18) -> 0
F15: 급여 | G15: 39.30703 | H15: 0 | I15: =G15+H15*$R$52/1000 -> 39.30703 | J15: 31.66514 | K15: 0 | L15: =J15+K15*$R$52/1000 -> 31.66514 | M15: 14.831917 | N15: 0 | O15: =M15+N15*$R$52/1000 -> 14.831917 | P15: 15.263567 | Q15: 0 | R15: =P15+Q15*$R$52/1000 -> 15.263567 | S15: 14.856137 | T15: 0 | U15: =S15+T15*U52/1000 -> 14.856137 | V15: 14.855137 | W15: 0 | X15: =V15+W15*X52/1000 -> 14.855137 | Y15: 14.816477 | Z15: 0 | AA15: =Y15+Z15*AA52/1000 -> 14.816477 | AB15: 15 | AC15: 0 | AD15: =AB15+AC15*AD52/1000 -> 15 | AG15: =AE15+AF15*AG52/1000 -> 0 | AJ15: =AH15+AI15*AJ52/1000 -> 0 | AM15: =AK15+AL15*AM52/1000 -> 0 | AP15: =AN15+AO15*AP52/1000 -> 0 | AS15: =AQ15+AR15*AS52/1000 -> 0 | AT15: =AQ15/$AW$3 -> 0 | AU15: =SUM(K15,N15,Q15,T15,W15,Z15,AC15,AF15,AI15,AL15,AO15,AR15) -> 0 | AV15: =AT15+AU15*AV52/1000 -> 0
F16: 상여 | G16: 0 | H16: 0 | I16: =G16+H16*$R$52/1000 -> 0 | J16: 0 | K16: 0 | L16: =J16+K16*$R$52/1000 -> 0 | M16: 0 | N16: 0 | O16: =M16+N16*$R$52/1000 -> 0 | P16: 0 | Q16: 0 | R16: =P16+Q16*$R$52/1000 -> 0 | S16: 0 | T16: 0 | U16: =S16+T16*U52/1000 -> 0 | V16: 0 | W16: 0 | X16: =V16+W16*X52/1000 -> 0 | Y16: 0 | Z16: 0 | AA16: =Y16+Z16*AA52/1000 -> 0 | AB16: 0 | AC16: 0 | AD16: =AB16+AC16*AD52/1000 -> 0 | AG16: =AE16+AF16*AG52/1000 -> 0 | AJ16: =AH16+AI16*AJ52/1000 -> 0 | AM16: =AK16+AL16*AM52/1000 -> 0 | AP16: =AN16+AO16*AP52/1000 -> 0 | AS16: =AQ16+AR16*AS52/1000 -> 0 | AT16: =AQ16/$AW$3 -> 0 | AU16: =SUM(K16,N16,Q16,T16,W16,Z16,AC16,AF16,AI16,AL16,AO16,AR16) -> 0 | AV16: =AT16+AU16*AV52/1000 -> 0
F17: 퇴직연금 | G17: 0 | H17: 0 | I17: =G17+H17*$R$52/1000 -> 0 | J17: 2.86999 | K17: 0 | L17: =J17+K17*$R$52/1000 -> 2.86999 | M17: 1.91806 | N17: 0 | O17: =M17+N17*$R$52/1000 -> 1.91806 | P17: 1.92848 | Q17: 0 | R17: =P17+Q17*$R$52/1000 -> 1.92848 | S17: 1.92848 | T17: 0 | U17: =S17+T17*U52/1000 -> 1.92848 | V17: 1.92848 | W17: 0 | X17: =V17+W17*X52/1000 -> 1.92848 | Y17: 1.92848 | Z17: 0 | AA17: =Y17+Z17*AA52/1000 -> 1.92848 | AB17: 1.92848 | AC17: 0 | AD17: =AB17+AC17*AD52/1000 -> 1.92848 | AG17: =AE17+AF17*AG52/1000 -> 0 | AJ17: =AH17+AI17*AJ52/1000 -> 0 | AM17: =AK17+AL17*AM52/1000 -> 0 | AP17: =AN17+AO17*AP52/1000 -> 0 | AS17: =AQ17+AR17*AS52/1000 -> 0 | AT17: =AQ17/$AW$3 -> 0 | AU17: =SUM(K17,N17,Q17,T17,W17,Z17,AC17,AF17,AI17,AL17,AO17,AR17) -> 0 | AV17: =AT17+AU17*AV52/1000 -> 0
F18: 4대보험료 | G18: 4.3279 | H18: 0 | I18: =G18+H18*$R$52/1000 -> 4.3279 | J18: 4.4573 | K18: 0 | L18: =J18+K18*$R$52/1000 -> 4.4573 | M18: 3.49646 | N18: 0 | O18: =M18+N18*$R$52/1000 -> 3.49646 | P18: 2.94166 | Q18: 0 | R18: =P18+Q18*$R$52/1000 -> 2.94166 | S18: 2.20456 | T18: 0 | U18: =S18+T18*U52/1000 -> 2.20456 | V18: 3.02442 | W18: 0 | X18: =V18+W18*X52/1000 -> 3.02442 | Y18: 2.92467 | Z18: 0 | AA18: =Y18+Z18*AA52/1000 -> 2.92467 | AB18: 3.00399 | AC18: 0 | AD18: =AB18+AC18*AD52/1000 -> 3.00399 | AG18: =AE18+AF18*AG52/1000 -> 0 | AJ18: =AH18+AI18*AJ52/1000 -> 0 | AM18: =AK18+AL18*AM52/1000 -> 0 | AP18: =AN18+AO18*AP52/1000 -> 0 | AS18: =AQ18+AR18*AS52/1000 -> 0 | AT18: =AQ18/$AW$3 -> 0 | AU18: =SUM(K18,N18,Q18,T18,W18,Z18,AC18,AF18,AI18,AL18,AO18,AR18) -> 0 | AV18: =AT18+AU18*AV52/1000 -> 0
E19: 마케팅비 | G19: 0 | H19: 0 | I19: =G19+H19*$R$52/1000 -> 0 | J19: 0 | K19: 0 | L19: =J19+K19*$R$52/1000 -> 0 | M19: 0 | N19: 0 | O19: =M19+N19*$R$52/1000 -> 0 | P19: 0 | Q19: 0 | R19: =P19+Q19*$R$52/1000 -> 0 | S19: 0 | T19: 0 | U19: =S19+T19*U52/1000 -> 0 | V19: 0 | W19: 0 | X19: =V19+W19*X52/1000 -> 0 | Y19: 0 | Z19: 0 | AA19: =Y19+Z19*AA52/1000 -> 0 | AB19: 0 | AC19: 0 | AD19: =AB19+AC19*AD52/1000 -> 0 | AE19: 0 | AF19: 0 | AG19: =AE19+AF19*AG52/1000 -> 0 | AH19: 0 | AI19: 0 | AJ19: =AH19+AI19*AJ52/1000 -> 0 | AK19: 0 | AL19: 0 | AM19: =AK19+AL19*AM52/1000 -> 0 | AN19: 0 | AO19: 0 | AP19: =AN19+AO19*AP52/1000 -> 0 | AQ19: =SUM(G19,J19,M19,P19,S19,V19,Y19,AB19,AE19,AH19,AK19,AN19) -> 0 | AR19: =SUM(H19,K19,N19,Q19,T19,W19,Z19,AC19,AF19,AI19,AL19,AO19) -> 0 | AS19: =AQ19+AR19*AS52/1000 -> 0 | AT19: =AQ19/$AW$3 -> 0 | AU19: =SUM(K19,N19,Q19,T19,W19,Z19,AC19,AF19,AI19,AL19,AO19,AR19) -> 0 | AV19: =AT19+AU19*AV52/1000 -> 0
E20: 제세공과금 | G20: =SUM(G21:G24) -> 4.93922 | H20: =SUM(H21:H24) -> 0 | I20: =SUM(I21:I24) -> 4.93922 | J20: =SUM(J21:J24) -> 5.2613 | K20: =SUM(K21:K24) -> 0 | L20: =SUM(L21:L24) -> 5.2613 | M20: =SUM(M21:M24) -> 0 | N20: =SUM(N21:N24) -> 0 | ... AN20: =SUM(AN21:AN24) -> 0 | AP20: =SUM(AP21:AP24) -> 0 | AQ20: =SUM(AQ21:AQ24) -> 0 | AS20: =SUM(AS21:AS24) -> 0 | AT20: =SUM(AT21:AT24) -> 0 | AV20: =SUM(AV21:AV24) -> 0
F21: 법인세 | G21: 0 | H21: 0 | I21: =G21+H21*$R$52/1000 -> 0 | J21: 0 | K21: 0 | L21: =J21+K21*$R$52/1000 -> 0 | M21: 0 | N21: 0 | O21: =M21+N21*$R$52/1000 -> 0 | P21: 0 | R21: =P21+Q21*$R$52/1000 -> 0 | S21: 0 | T21: 0 | U21: =S21+T21*U52/1000 -> 0 | V21: 0 | W21: 0 | X21: =V21+W21*X52/1000 -> 0 | Y21: 0 | Z21: 0 | AA21: =Y21+Z21*AA52/1000 -> 0 | AB21: 0 | AC21: 0 | AD21: =AB21+AC21*AD52/1000 -> 0 | AG21: =AE21+AF21*AG52/1000 -> 0 | AJ21: =AH21+AI21*AJ52/1000 -> 0 | AM21: =AK21+AL21*AM52/1000 -> 0 | AP21: =AN21+AO21*AP52/1000 -> 0 | AS21: =AQ21+AR21*AS52/1000 -> 0 | AT21: =AQ21/$AW$3 -> 0 | AU21: =SUM(K21,N21,Q21,T21,W21,Z21,AC21,AF21,AI21,AL21,AO21,AR21) -> 0 | AV21: =AT21+AU21*AV52/1000 -> 0
F22: 부가가치세 | G22: 0 | H22: 0 | I22: =G22+H22*$R$52/1000 -> 0 | J22: 0 | K22: 0 | L22: =J22+K22*$R$52/1000 -> 0 | M22: 0 | N22: 0 | O22: =M22+N22*$R$52/1000 -> 0 | P22: 0 | R22: =P22+Q22*$R$52/1000 -> 0 | S22: 0 | T22: 0 | U22: =S22+T22*$U52/1000 -> 0 | V22: 0 | W22: 0 | X22: =V22+W22*$U52/1000 -> 0 | Y22: 3.65935 | Z22: 0 | AA22: =Y22+Z22*$U52/1000 -> 3.65935 | AB22: 0 | AC22: 0 | AD22: =AB22+AC22*$U52/1000 -> 0 | AG22: =AE22+AF22*$U52/1000 -> 0 | AJ22: =AH22+AI22*$U52/1000 -> 0 | AM22: =AK22+AL22*$U52/1000 -> 0 | AP22: =AN22+AO22*$U52/1000 -> 0 | AS22: =AQ22+AR22*$U52/1000 -> 0 | AT22: =AQ22/$AW$3 -> 0 | AU22: =SUM(K22,N22,Q22,T22,W22,Z22,AC22,AF22,AI22,AL22,AO22,AR22) -> 0 | AV22: =AT22+AU22*$U52/1000 -> 0
F23: 원천세 | G23: 4.93922 | H23: 0 | I23: =G23+H23*$R$52/1000 -> 4.93922 | J23: 5.2613 | K23: 0 | L23: =J23+K23*$R$52/1000 -> 5.2613 | M23: 0 | N23: 0 | O23: =M23+N23*$R$52/1000 -> 0 | P23: 0 | R23: =P23+Q23*$R$52/1000 -> 0 | T23: 0 | U23: =S23+T23*U52/1000 -> 0 | V23: 1.75016 | W23: 0 | X23: =V23+W23*X52/1000 -> 1.75016 | Y23: 3.92024 | Z23: 0 | AA23: =Y23+Z23*AA52/1000 -> 3.92024 | AB23: 3.92024 | AC23: 0 | AD23: =AB23+AC23*AD52/1000 -> 3.92024 | AG23: =AE23+AF23*AG52/1000 -> 0 | AJ23: =AH23+AI23*AJ52/1000 -> 0 | AM23: =AK23+AL23*AM52/1000 -> 0 | AP23: =AN23+AO23*AP52/1000 -> 0 | AS23: =AQ23+AR23*AS52/1000 -> 0 | AT23: =AQ23/$AW$3 -> 0 | AU23: =SUM(K23,N23,Q23,T23,W23,Z23,AC23,AF23,AI23,AL23,AO23,AR23) -> 0 | AV23: =AT23+AU23*AV52/1000 -> 0
F24: 기타제세공과금 | G24: 0 | H24: 0 | I24: =G24+H24*$R$52/1000 -> 0 | J24: 0 | K24: 0 | L24: =J24+K24*$R$52/1000 -> 0 | M24: 0 | N24: 0 | O24: =M24+N24*$R$52/1000 -> 0 | P24: 0 | R24: =P24+Q24*$R$52/1000 -> 0 | S24: 0 | T24: 0 | U24: =S24+T24*U52/1000 -> 0 | V24: 0 | W24: 0 | X24: =V24+W24*X52/1000 -> 0 | Y24: 0 | Z24: 0 | AA24: =Y24+Z24*AA52/1000 -> 0 | AB24: 0.25 | AC24: 0 | AD24: =AB24+AC24*AD52/1000 -> 0.25 | AG24: =AE24+AF24*AG52/1000 -> 0 | AJ24: =AH24+AI24*AJ52/1000 -> 0 | AM24: =AK24+AL24*AM52/1000 -> 0 | AP24: =AN24+AO24*AP52/1000 -> 0 | AS24: =AQ24+AR24*AS52/1000 -> 0 | AT24: =AQ24/$AW$3 -> 0 | AU24: =SUM(K24,N24,Q24,T24,W24,Z24,AC24,AF24,AI24,AL24,AO24,AR24) -> 0 | AV24: =AT24+AU24*AV52/1000 -> 0
E25: 지급이자 | G25: 0 | H25: 0 | I25: =G25+H25*$R$52/1000 -> 0 | J25: 0 | K25: 0 | L25: =J25+K25*$R$52/1000 -> 0 | M25: 0 | N25: 0 | O25: =M25+N25*$R$52/1000 -> 0 | P25: 0 | Q25: 0 | R25: =P25+Q25*$R$52/1000 -> 0 | S25: 0 | T25: 0 | U25: =S25+T25*U52/1000 -> 0 | V25: 0 | W25: 0 | X25: =V25+W25*X52/1000 -> 0 | Y25: 0 | Z25: 0 | AA25: =Y25+Z25*AA52/1000 -> 0 | AB25: 0 | AC25: 0 | AD25: =AB25+AC25*AD52/1000 -> 0 | AE25: 0 | AF25: 0 | AG25: =AE25+AF25*AG52/1000 -> 0 | AH25: 0 | AI25: 0 | AJ25: =AH25+AI25*AJ52/1000 -> 0 | AK25: 0 | AL25: 0 | AM25: =AK25+AL25*AM52/1000 -> 0 | AN25: 0 | AO25: 0 | AP25: =AN25+AO25*AP52/1000 -> 0 | AQ25: =SUM(G25,J25,M25,P25,S25,V25,Y25,AB25,AE25,AH25,AK25,AN25) -> 0 | AR25: =SUM(H25,K25,N25,Q25,T25,W25,Z25,AC25,AF25,AI25,AL25,AO25) -> 0 | AS25: =AQ25+AR25*AS52/1000 -> 0 | AT25: =AQ25/$AW$3 -> 0 | AU25: =SUM(K25,N25,Q25,T25,W25,Z25,AC25,AF25,AI25,AL25,AO25,AR25) -> 0 | AV25: =AT25+AU25*AV52/1000 -> 0
E26: 자산매입 | G26: 0 | H26: 0 | I26: =G26+H26*$R$52/1000 -> 0 | J26: 0 | K26: 0 | L26: =J26+K26*$R$52/1000 -> 0 | M26: 0 | N26: 0 | O26: =M26+N26*$R$52/1000 -> 0 | P26: 0 | Q26: 0 | R26: =P26+Q26*$R$52/1000 -> 0 | S26: 0 | T26: 0 | U26: =S26+T26*U52/1000 -> 0 | W26: 0 | X26: =V26+W26*X52/1000 -> 0 | Y26: 0 | Z26: 0 | AA26: =Y26+Z26*AA52/1000 -> 0 | AB26: 0 | AC26: 0 | AD26: =AB26+AC26*AD52/1000 -> 0 | AE26: 0 | AF26: 0 | AG26: =AE26+AF26*AG52/1000 -> 0 | AH26: 0 | AI26: 0 | AJ26: =AH26+AI26*AJ52/1000 -> 0 | AK26: 0 | AL26: 0 | AM26: =AK26+AL26*AM52/1000 -> 0 | AN26: 0 | AO26: 0 | AP26: =AN26+AO26*AP52/1000 -> 0 | AQ26: =SUM(G26,J26,M26,P26,S26,V26,Y26,AB26,AE26,AH26,AK26,AN26) -> 0 | AR26: =SUM(H26,K26,N26,Q26,T26,W26,Z26,AC26,AF26,AI26,AL26,AO26) -> 0 | AS26: =AQ26+AR26*AS52/1000 -> 0 | AT26: =AQ26/$AW$3 -> 0 | AU26: =SUM(K26,N26,Q26,T26,W26,Z26,AC26,AF26,AI26,AL26,AO26,AR26) -> 0 | AV26: =AT26+AU26*AV52/1000 -> 0
E27: 투자금 | G27: 0 | H27: 0 | I27: =G27+H27*$R$52/1000 -> 0 | J27: 7.13645 | K27: 0 | L27: =J27+K27*$R$52/1000 -> 7.13645 | M27: 999.999 | N27: 0 | O27: =M27+N27*$R$52/1000 -> 999.999 | P27: 0 | Q27: 0 | R27: =P27+Q27*$R$52/1000 -> 0 | S27: 0 | T27: 0 | U27: =S27+T27*U53/1000 -> 0 | W27: 0 | X27: =V27+W27*X53/1000 -> 0 | Y27: 0 | Z27: 0 | AA27: =Y27+Z27*AA53/1000 -> 0 | AB27: 0 | AC27: 0 | AD27: =AB27+AC27*AD53/1000 -> 0 | AE27: 0 | AF27: 0 | AG27: =AE27+AF27*AG53/1000 -> 0 | AH27: 0 | AI27: 0 | AJ27: =AH27+AI27*AJ53/1000 -> 0 | AK27: 0 | AL27: 0 | AM27: =AK27+AL27*AM53/1000 -> 0 | AN27: 0 | AO27: 0 | AP27: =AN27+AO27*AP53/1000 -> 0 | AQ27: =SUM(G27,J27,M27,P27,S27,V27,Y27,AB27,AE27,AH27,AK27,AN27) -> 1007.1354 | AR27: =SUM(H27,K27,N27,Q27,T27,W27,Z27,AC27,AF27,AI27,AL27,AO27) -> 0 | AS27: =AQ27+AR27*AS53/1000 -> 1007.1354 | AT27: =AQ27/$AW$3 -> 83.927954 | AU27: =SUM(K27,N27,Q27,T27,W27,Z27,AC27,AF27,AI27,AL27,AO27,AR27) -> 0 | AV27: =AT27+AU27*AV53/1000 -> 83.927954
E28: 기타 | G28: =SUM(G29:G32) -> 14.166859 | H28: =SUM(H29:H32) -> 0 | I28: =SUM(I29:I32) -> 14.166859 | J28: =SUM(J29:J32) -> 13.619629 | K28: =SUM(K29:K32) -> 0 | L28: =SUM(L29:L32) -> 13.619629 | M28: =SUM(M29:M32) -> 6.510076 | N28: 0 | O28: =SUM(O29:O32) -> 6.510076 | P28: =SUM(P29:P32) -> 11.410589 | Q28: =SUM(Q29:Q32) -> 0 | R28: =SUM(R29:R32) -> 11.410589 | S28: =SUM(S29:S32) -> 15.245221 | T28: =SUM(T29:T32) -> 0 | U28: =SUM(U29:U32) -> 15.245221 | V28: =SUM(V29:V32) -> 11.238781 | ... Y28: =SUM(Y29:Y32) -> 14.0237 | Z28: 0 | AA28: =SUM(AA29:AA32) -> 14.0237 | AB28: =SUM(AB29:AB32) -> 6.989428 | AC28: =SUM(AC29:AC32) -> 0 | AD28: =SUM(AD29:AD32) -> 6.989428 | AE28: =SUM(AE29:AE32) -> 0 | AF28: =SUM(AF29:AF32) -> 0 | AG28: =SUM(AG29:AG32) -> 0 | AH28: =SUM(AH29:AH32) -> 0 | ... AV28: =SUM(AV29:AV32) -> 0
F29: 전산관련지출 | G29: 0.78595 | H29: 0 | I29: =G29+H29*$R$52/1000 -> 0.78595 | J29: 2.840809 | K29: 0 | L29: =J29+K29*$R$52/1000 -> 2.840809 | M29: 0.910306 | N29: 0 | O29: =M29+N29*$R$52/1000 -> 0.910306 | P29: 0.708204 | Q29: 0 | R29: =P29+Q29*$R$52/1000 -> 0.708204 | S29: 0.826483 | T29: 0 | U29: =S29+T29*U52/1000 -> 0.826483 | V29: 1.41149 | W29: 0 | X29: =V29+W29*X52/1000 -> 1.41149 | Y29: 0.685391 | Z29: 0 | AA29: =Y29+Z29*AA52/1000 -> 0.685391 | AB29: 0.685025 | AC29: 0 | AD29: =AB29+AC29*AD56/1000 -> 0.685025 | AG29: =AE29+AF29*AG52/1000 -> 0 | AJ29: =AH29+AI29*AJ52/1000 -> 0 | AM29: =AK29+AL29*AM52/1000 -> 0 | AP29: =AN29+AO29*AP52/1000 -> 0 | AS29: =AQ29+AR29*AS52/1000 -> 0 | AT29: =AQ29/$AW$3 -> 0 | AU29: =SUM(K29,N29,Q29,T29,W29,Z29,AC29,AF29,AI29,AL29,AO29,AR29) -> 0 | AV29: =AT29+AU29*AV52/1000 -> 0
F30: 개발 외주용역비 | G30: 0 | H30: 0 | I30: =G30+H30*$R$52/1000 -> 0 | J30: 0 | K30: 0 | L30: =J30+K30*$R$52/1000 -> 0 | M30: 0 | N30: 0 | O30: =M30+N30*$R$52/1000 -> 0 | P30: 0 | Q30: 0 | R30: =P30+Q30*$R$52/1000 -> 0 | S30: 0 | T30: 0 | U30: =S30+T30*U52/1000 -> 0 | V30: 0 | W30: 0 | X30: =V30+W30*X52/1000 -> 0 | Y30: 0 | Z30: 0 | AA30: =Y30+Z30*AA52/1000 -> 0 | AB30: 0 | AC30: 0 | AD30: =AB30+AC30*AD57/1000 -> 0 | AG30: =AE30+AF30*AG52/1000 -> 0 | AJ30: =AH30+AI30*AJ52/1000 -> 0 | AM30: =AK30+AL30*AM52/1000 -> 0 | AP30: =AN30+AO30*AP52/1000 -> 0 | AS30: =AQ30+AR30*AS52/1000 -> 0 | AT30: =AQ30/$AW$3 -> 0 | AU30: =SUM(K30,N30,Q30,T30,W30,Z30,AC30,AF30,AI30,AL30,AO30,AR30) -> 0 | AV30: =AT30+AU30*AV52/1000 -> 0
F31: 경영, 업무지원, 운영용역비 | G31: 3.557324 | H31: 0 | I31: =G31+H31*$R$52/1000 -> 3.557324 | J31: 0.061712 | K31: 0 | L31: =J31+K31*$R$52/1000 -> 0.061712 | M31: 0.04229 | N31: 0 | O31: =M31+N31*$R$52/1000 -> 0.04229 | P31: 3.349059 | Q31: 0 | R31: =P31+Q31*$R$52/1000 -> 3.349059 | S31: 0.044597 | T31: 0 | U31: =S31+T31*U52/1000 -> 0.044597 | V31: 0.044976 | W31: 0 | X31: =V31+W31*X52/1000 -> 0.044976 | Y31: 3.309631 | Z31: 0 | AA31: =Y31+Z31*AA52/1000 -> 3.309631 | AB31: 0.043689 | AC31: 0 | AD31: =AB31+AC31*AD58/1000 -> 0.043689 | AG31: =AE31+AF31*AG52/1000 -> 0 | AJ31: =AH31+AI31*AJ52/1000 -> 0 | AM31: =AK31+AL31*AM52/1000 -> 0 | AP31: =AN31+AO31*AP52/1000 -> 0 | AS31: =AQ31+AR31*AS52/1000 -> 0 | AT31: =AQ31/$AW$3 -> 0 | AU31: =SUM(K31,N31,Q31,T31,W31,Z31,AC31,AF31,AI31,AL31,AO31,AR31) -> 0 | AV31: =AT31+AU31*AV52/1000 -> 0
F32: 기타 | G32: =SUM(G33:G38) -> 9.823585 | H32: =SUM(H33:H38) -> 0 | I32: =SUM(I33:I38) -> 9.823585 | J32: =SUM(J33:J38) -> 10.717108 | K32: =SUM(K33:K38) -> 0 | L32: =SUM(L33:L38) -> 10.717108 | M32: =SUM(M33:M38) -> 5.55748 | N32: =SUM(N33:N38) -> 0 | ... AD32: =SUM(AD33:AD38) -> 6.260714 | AG32: =AE32+AF32*AG52/1000 -> 0 | AJ32: =AH32+AI32*AJ52/1000 -> 0 | AM32: =AK32+AL32*AM52/1000 -> 0 | AP32: =AN32+AO32*AP52/1000 -> 0 | AS32: =AQ32+AR32*AS52/1000 -> 0 | AT32: =AQ32/$AW$3 -> 0 | AU32: =SUM(K32,N32,Q32,T32,W32,Z32,AC32,AF32,AI32,AL32,AO32,AR32) -> 0 | AV32: =AT32+AU32*AV52/1000 -> 0
F33: 복리후생비 | G33: 1.678515 | H33: 0 | I33: =G33+H33*I$52/1000 -> 1.678515 | J33: 0.660082 | K33: 0 | L33: =J33+K33*L$52/1000 -> 0.660082 | M33: 1.26286 | N33: 0 | O33: =M33+N33*O$52/1000 -> 1.26286 | P33: 0 | Q33: 0 | R33: =P33+Q33*R$52/1000 -> 0 | S33: 1.681931 | T33: 0 | U33: =S33+T33*U$52/1000 -> 1.681931 | V33: 1.778205 | W33: 0 | X33: =V33+W33*X$52/1000 -> 1.778205 | Y33: 0.156247 | Z33: 0 | AA33: =Y33+Z33*AA$52/1000 -> 0.156247 | AB33: 0.154956 | AC33: 0 | AD33: =AB33+AC33*AD$52/1000 -> 0.154956 | AU33: =SUM(K33,N33,Q33,T33,W33,Z33,AC33,AF33,AI33,AL33,AO33,AR33) -> 0
F34: 식당, 카페 등 운영비 | G34: 0.311 | H34: 0 | I34: =G34+H34*I$52/1000 -> 0.311 | J34: 0.165 | K34: 0 | L34: =J34+K34*L$52/1000 -> 0.165 | M34: 0.1392 | N34: 0 | O34: =M34+N34*O$52/1000 -> 0.1392 | P34: 0.165 | Q34: 0 | R34: =P34+Q34*R$52/1000 -> 0.165 | S34: 0.145 | T34: 0 | U34: =S34+T34*U$52/1000 -> 0.145 | V34: 0.084 | W34: 0 | X34: =V34+W34*X$52/1000 -> 0.084 | Y34: 0 | Z34: 0 | AA34: =Y34+Z34*AA$52/1000 -> 0 | AB34: 0.2297 | AC34: 0 | AD34: =AB34+AC34*AD$52/1000 -> 0.2297 | AU34: =SUM(K34,N34,Q34,T34,W34,Z34,AC34,AF34,AI34,AL34,AO34,AR34) -> 0
F35: 직원비용, 복지포인트 | G35: 5.325892 | H35: 0 | I35: =G35+H35*I$52/1000 -> 5.325892 | J35: 5.21776 | K35: 0 | L35: =J35+K35*L$52/1000 -> 5.21776 | M35: 2.364157 | N35: 0 | O35: =M35+N35*O$52/1000 -> 2.364157 | P35: 5.869168 | Q35: 0 | R35: =P35+Q35*R$52/1000 -> 5.869168 | S35: 9.481778 | T35: 0 | U35: =S35+T35*U$52/1000 -> 9.481778 | V35: 4.467447 | W35: 0 | X35: =V35+W35*X$52/1000 -> 4.467447 | Y35: 8.717161 | Z35: 0 | AA35: =Y35+Z35*AA$52/1000 -> 8.717161 | AB35: 4.028322 | AC35: 0 | AD35: =AB35+AC35*AD$52/1000 -> 4.028322 | AU35: =SUM(K35,N35,Q35,T35,W35,Z35,AC35,AF35,AI35,AL35,AO35,AR35) -> 0
F36: 임차료, 관리비 | G36: 0.919248 | H36: 0 | I36: =G36+H36*I$52/1000 -> 0.919248 | J36: 0.919248 | K36: 0 | L36: =J36+K36*L$52/1000 -> 0.919248 | M36: 0.919248 | N36: 0 | O36: =M36+N36*O$52/1000 -> 0.919248 | P36: 0.919248 | Q36: 0 | R36: =P36+Q36*R$52/1000 -> 0.919248 | S36: 0.919248 | T36: 0 | U36: =S36+T36*U$52/1000 -> 0.919248 | V36: 0.919248 | W36: 0 | X36: =V36+W36*X$52/1000 -> 0.919248 | Y36: 0.919248 | Z36: 0 | AA36: =Y36+Z36*AA$52/1000 -> 0.919248 | AB36: 0.919248 | AC36: 0 | AD36: =AB36+AC36*AD$52/1000 -> 0.919248 | AU36: =SUM(K36,N36,Q36,T36,W36,Z36,AC36,AF36,AI36,AL36,AO36,AR36) -> 0
F37: 지급수수료 | G37: 0.001 | H37: 0 | I37: =G37+H37*I$52/1000 -> 0.001 | J37: 0 | K37: 0 | L37: =J37+K37*L$52/1000 -> 0 | M37: 0.636795 | N37: 0 | O37: =M37+N37*O$52/1000 -> 0.636795 | P37: 0 | Q37: 0 | R37: =P37+Q37*R$52/1000 -> 0 | S37: 1.701073 | T37: 0 | U37: =S37+T37*U$52/1000 -> 1.701073 | V37: 2.298395 | W37: 0 | X37: =V37+W37*X$52/1000 -> 2.298395 | Y37: 0 | Z37: 0 | AA37: =Y37+Z37*AA$52/1000 -> 0 | AB37: 0.476281 | AC37: 0 | AD37: =AB37+AC37*AD$52/1000 -> 0.476281 | AU37: =SUM(K37,N37,Q37,T37,W37,Z37,AC37,AF37,AI37,AL37,AO37,AR37) -> 0
F38: 통신비등 | G38: 1.58793 | H38: 0 | I38: =G38+H38*I$52/1000 -> 1.58793 | J38: 3.755018 | K38: 0 | L38: =J38+K38*L$52/1000 -> 3.755018 | M38: 0.23522 | N38: 0 | O38: =M38+N38*O$52/1000 -> 0.23522 | P38: 0.39991 | Q38: 0 | R38: =P38+Q38*R$52/1000 -> 0.39991 | S38: 0.445111 | T38: 0 | U38: =S38+T38*U$52/1000 -> 0.445111 | V38: 0.23502 | W38: 0 | X38: =V38+W38*X$52/1000 -> 0.23502 | Y38: 0.236022 | Z38: 0 | AA38: =Y38+Z38*AA$52/1000 -> 0.236022 | AB38: 0.452207 | AC38: 0 | AD38: =AB38+AC38*AD$52/1000 -> 0.452207 | AU38: =SUM(K38,N38,Q38,T38,W38,Z38,AC38,AF38,AI38,AL38,AO38,AR38) -> 0
C39: C. 운용자금 입지출(=해지-예치) | G39: =G40-G41 -> 900 | H39: =H40-H41 -> 0 | I39: =I40-I41 -> 900 | J39: =J40-J41 -> 0 | K39: =K40-K41 -> 0 | L39: =L40-L41 -> 0 | M39: =M40-M41 -> 0 | N39: =N40-N41 -> 0 | ... AV39: =AV40-AV41 -> 100
D40: 해지(입금) | G40: 900 | H40: =SUMIFS('7월데이터'!$E:$E,'7월데이터'!$A:$A,"금융상품",'7월데이터'!$D:$D,"USD")/1000 -> 0 | I40: =G40+H40*$R$52/1000 -> 900 | J40: 0 | K40: =SUMIFS('8월데이터'!$E:$E,'8월데이터'!$A:$A,"금융상품",'8월데이터'!$D:$D,"USD")/1000 -> 0 | L40: =J40+K40*$R$52/1000 -> 0 | N40: =SUMIFS('7월데이터'!$E:$E,'7월데이터'!$A:$A,"금융상품",'7월데이터'!$D:$D,"USD")/1000 -> 0 | O40: =M40+N40*$R$52/1000 -> 0 | P40: 0 | Q40: =SUMIFS('8월데이터'!$E:$E,'8월데이터'!$A:$A,"금융상품",'8월데이터'!$D:$D,"USD")/1000 -> 0 | R40: =P40+Q40*$R$52/1000 -> 0 | S40: 0 | T40: =SUMIFS('8월데이터'!$E:$E,'8월데이터'!$A:$A,"금융상품",'8월데이터'!$D:$D,"USD")/1000 -> 0 | U40: =S40+T40*U52/1000 -> 0 | V40: 300 | W40: 0 | X40: =V40+W40*X52/1000 -> 300 | Y40: 0 | Z40: =SUMIFS('8월데이터'!$E:$E,'8월데이터'!$A:$A,"금융상품",'8월데이터'!$D:$D,"USD")/1000 -> 0 | AA40: =Y40+Z40*AA52/1000 -> 0 | AB40: 0 | AC40: =SUMIFS('8월데이터'!$E:$E,'8월데이터'!$A:$A,"금융상품",'8월데이터'!$D:$D,"USD")/1000 -> 0 | AD40: =AB40+AC40*AD52/1000 -> 0 | AF40: =SUMIFS('8월데이터'!$E:$E,'8월데이터'!$A:$A,"금융상품",'8월데이터'!$D:$D,"USD")/1000 -> 0 | AG40: =AE40+AF40*AG52/1000 -> 0 | AH40: 0 | AI40: 0 | AJ40: =AH40+AI40*AJ52/1000 -> 0 | AK40: 0 | AL40: =SUMIFS('8월데이터'!$E:$E,'8월데이터'!$A:$A,"금융상품",'8월데이터'!$D:$D,"USD")/1000 -> 0 | AM40: =AK40+AL40*AM52/1000 -> 0 | AN40: 0 | AO40: =SUMIFS('8월데이터'!$E:$E,'8월데이터'!$A:$A,"금융상품",'8월데이터'!$D:$D,"USD")/1000 -> 0 | AP40: =AN40+AO40*AP52/1000 -> 0 | AQ40: =SUM(G40,J40,M40,P40,S40,V40,Y40,AB40,AE40,AH40,AK40,AN40) -> 1200 | AR40: =SUM(H40,K40,N40,Q40,T40,W40,Z40,AC40,AF40,AI40,AL40,AO40) -> 0 | AS40: =AQ40+AR40*AS52/1000 -> 1200 | AT40: =AQ40/AW3 -> 100 | AU40: =SUM(K40,N40,Q40,T40,W40,Z40,AC40,AF40,AI40,AL40,AO40,AR40) -> 0 | AV40: =AT40+AU40*AV52/1000 -> 100
D41: 예치(지출) | G41: 0 | H41: =SUMIFS('7월데이터'!$F:$F,'7월데이터'!$A:$A,"금융상품",'7월데이터'!$D:$D,"USD")/1000 -> 0 | I41: =G41+H41*$R$52/1000 -> 0 | J41: 0 | K41: =SUMIFS('8월데이터'!$F:$F,'8월데이터'!$A:$A,"금융상품",'8월데이터'!$D:$D,"USD")/1000 -> 0 | L41: =J41+K41*$R$52/1000 -> 0 | N41: =SUMIFS('7월데이터'!$F:$F,'7월데이터'!$A:$A,"금융상품",'7월데이터'!$D:$D,"USD")/1000 -> 0 | O41: =M41+N41*$R$52/1000 -> 0 | P41: 0 | Q41: =SUMIFS('8월데이터'!$F:$F,'8월데이터'!$A:$A,"금융상품",'8월데이터'!$D:$D,"USD")/1000 -> 0 | R41: =P41+Q41*$R$52/1000 -> 0 | S41: 0 | T41: =SUMIFS('8월데이터'!$F:$F,'8월데이터'!$A:$A,"금융상품",'8월데이터'!$D:$D,"USD")/1000 -> 0 | U41: =S41+T41*U52/1000 -> 0 | W41: 0 | X41: =V41+W41*X52/1000 -> 0 | Y41: 0 | Z41: =SUMIFS('8월데이터'!$F:$F,'8월데이터'!$A:$A,"금융상품",'8월데이터'!$D:$D,"USD")/1000 -> 0 | AA41: =Y41+Z41*AA52/1000 -> 0 | AB41: 0 | AC41: =SUMIFS('8월데이터'!$F:$F,'8월데이터'!$A:$A,"금융상품",'8월데이터'!$D:$D,"USD")/1000 -> 0 | AD41: =AB41+AC41*AD52/1000 -> 0 | AE41: 0 | AF41: =SUMIFS('8월데이터'!$F:$F,'8월데이터'!$A:$A,"금융상품",'8월데이터'!$D:$D,"USD")/1000 -> 0 | AG41: =AE41+AF41*AG52/1000 -> 0 | AH41: 0 | AI41: 0 | AJ41: =AH41+AI41*AJ52/1000 -> 0 | AK41: 0 | AL41: =SUMIFS('8월데이터'!$F:$F,'8월데이터'!$A:$A,"금융상품",'8월데이터'!$D:$D,"USD")/1000 -> 0 | AM41: =AK41+AL41*AM52/1000 -> 0 | AN41: 0 | AO41: =SUMIFS('8월데이터'!$F:$F,'8월데이터'!$A:$A,"금융상품",'8월데이터'!$D:$D,"USD")/1000 -> 0 | AP41: =AN41+AO41*AP52/1000 -> 0 | AQ41: =SUM(G41,J41,M41,P41,S41,V41,Y41,AB41,AE41,AH41,AK41,AN41) -> 0 | AR41: =SUM(H41,K41,N41,Q41,T41,W41,Z41,AC41,AF41,AI41,AL41,AO41) -> 0 | AS41: =AQ41+AR41*AS52/1000 -> 0 | AT41: =AQ41/AW3 -> 0 | AU41: =SUM(K41,N41,Q41,T41,W41,Z41,AC41,AF41,AI41,AL41,AO41,AR41) -> 0 | AV41: =AT41+AU41*AV52/1000 -> 0
...

Sheet 7월데이터
A1: 7월 자금실적 | H1: USD | I1: 1541.5
A3: 구분 | B3: 업체명 | C3: 적요 | D3: 통화 | E3: 입금 | F3: 출금 | G3: 외화금액
A4: 기타 | B4: 하나은행 | C4: 잔액증명서발급수수료(7/1) | D4: KRW | F4: 1000
A5: 원천세 | B5: 금천세무서 | C5: 2026년 6월 근로소득세 원천징수(7/9) | D5: KRW | F5: 3563860
A6: 원천세 | B6: 금천구청 | C6: 2026년 6월 근로소득주민세 원천징수(7/9) | D6: KRW | F6: 356380
A7: 4대보험 | B7: 건강보험공단 | C7: 건강보험료(7/10) | D7: KRW | F7: 1678060
A8: 4대보험 | B8: 국민연금공단 | C8: 국민연금 보험료(7/10) | D8: KRW | F8: 1085920
A9: 4대보험 | B9: 고용보험공단 | C9: 고용보험료(7/10) | D9: KRW | F9: 117760
A10: 4대보험 | B10: 고용보험공단 | C10: 산재보험료(7/10) | D10: KRW | F10: 42930
A11: 기타 | B11: ㈜비즈마켓 | C11: 복지포인트 2분기 상계금액 환급(7/10) | D11: KRW | E11: 78020
A12: 퇴직연금 | B12: 기업은행 | C12: 임직원 퇴직연금_기업은행 | D12: KRW | F12: 1466670
A13: 퇴직연금 | B13: 한국투자증권 | C13: 임직원 퇴직연금_한국투자증권 | D13: KRW | F13: 461810
A14: 기타 | B14: 주식회사 세포아소프트 | C14: 법인카드데이타 연동서비스 | D14: KRW | F14: 110000
A15: 기타 | B15: 아름다운세차 | C15: 임원 복리후생(정기세차) 비용 납부 | D15: KRW | F15: 99000
A16: 복리후생비 | B16: 삼성웰스토리(주)컴투스 | C16: 사내식당 임직원 식대 | D16: KRW | F16: 96000
A17: 복리후생비 | B17: 최민준 | C17: 주택자금대출 이자지원 | D17: KRW | F17: 59247
A18: 복리후생비 | B18: 카페 어썸 | C18: 사내카페 운영비용 | D18: KRW | F18: 1000
A19: 직원비용 | B19: 임직원 | C19: 260720직원경비(7/20) | D19: KRW | F19: 8717161
A20: 경영지원용역비 | B20: (주)컴투스 | C20: 회계 등 경영부문 용역료 지급 | D20: KRW | F20: 2970000
A21: 지급임차료 | B21: (주)컴투스 | C21: BYC 하이시티 B동 24층 월정임차료 | D21: KRW | F21: 919248
A22: 경영지원용역비 | B22: (주)컴투스 | C22: 4사 공용비용 지급 | D22: KRW | F22: 295375
A23: 경영지원용역비 | B23: (주)컴투스 | C23: 인사 용역료 지급 | D23: KRW | F23: 44256
... A31: 기타 | B31: LG U+ | C31: 인터넷 전화 및 음성회의 전화요금 | D31: KRW | F31: 3150
A32: 외상매출금 | B32: 컴투스플랫폼 | C32: 서버비 정산금(7/31) | D32: KRW | E32: 56328
D33: KRW
D34: KRW
D35: KRW
D36: KRW
D37: KRW
D38: KRW
D39: KRW
D40: KRW
D41: KRW
D42: KRW
D43: KRW
D44: KRW
... D47: KRW

Sheet 8월데이터
A1: 8월 자금계획 | G1: 환율 | H1: USD | I1: 1541.5
A3: 구분 | B3: 업체명 | C3: 적요 | D3: 통화 | E3: 입금 | F3: 출금 | G3: 외화금액
A4: 투자금 | D4: KRW
A5: 투자금 | D5: KRW
A6: 금융상품 | B6: 하나은행 | C6: 정기예금 3억원 만기 해지(6/22) | D6: KRW
A7: 이자수익 | B7: 하나은행 | C7: 정기예금 3억원 만기 해지 이자 입금(6/22) | D7: KRW
A8: 금융상품 | B8: 하나은행 | C8: 하나/정기예금/3억/6M | D8: KRW
A9: 금융상품 | B9: 하나은행 | C9: 펀드 일부 해지 | D9: KRW
A10: 이자수익 | B10: 하나은행 | C10: 펀드 일부 해지 수익 입금 | D10: KRW
A11: 세금환급 | B11: 금천구 | C11: 법인세 환급 | D11: KRW
A12: 세금환급 | B12: 금천구 | C12: 법인지방소득세 환급 | D12: KRW
A13: 세금환급 | B13: 금천세무서 | C13: 부가가치세 환급(5월중순) | D13: KRW
A14: 부가가치세 | B14: 금천세무서 | C14: 부가가치세 신고 (다음 환급일 : 4월) | D14: KRW
A15: 투자금 | B15: 에이탑유니버스 | C15: 신주인수 투자금 납입 | D15: KRW
A16: 기타 | B16: 주식회사 세포아소프트 | C16: 법인카드 데이터 연동시스템 사용 | D16: KRW | F16: 110000
A17: 경영지원용역비 | B17: ㈜컴투스 | C17: 인사 용역료 | D17: KRW | F17: 43689
A18: 경영지원용역비 | B18: ㈜컴투스홀딩스 | C18: 전산자산 운용 용역료 | D18: KRW
A19: 경영지원용역비 | B19: ㈜컴투스 | C19: 분기별 경영부문 용역료 | D19: KRW
A20: 경영지원용역비 | B20: ㈜컴투스 | C20: 분기별 그룹사 공용비용 | D20: KRW
A21: 기타 | B21: ㈜컴투스 | C21: 컨벤션 행사 서비스 용역료 | D21: KRW
A22: 기타 | B22: ㈜컴투스 | C22: 상표권 로열티 | D22: KRW
A23: 지급임차료 | B23: ㈜컴투스 | C23: 월정임차료 및 관리비 | D23: KRW | F23: 919248
A24: 기타 | B24: LG유플러스 | C24: 대표번호 전화요금 | D24: KRW | F24: 18700
A25: 세금환급 | B25: 금천세무서 | C25: 법인세 환급 | D25: KRW
A26: 세금환급 | B26: 금천구청 | C26: 법인지방소득세 환급 | D26: KRW
A27: 부가가치세 | B27: 금천세무서 | C27: 예정/확정 부가가치세 납부 | D27: KRW
A28: 기타 | B28: ㈜컴투스플랫폼 | C28: 컨벤션 공동운영 수익 배분 | D28: KRW
A29: 기타 | B29: ㈜컴투스플랫폼 | C29: 컨벤션 행사 서버비 분담금 | D29: KRW
A30: 기타제세공과금 | B30: 금천구청 | C30: 사업소분 주민세 납부 | D30: KRW | F30: 250000
A31: 복리후생비 | B31: 임직원 | C31: 주택자금대출 이자지원 | D31: KRW | F31: 55956
A32: 식당운영비 | B32: 삼성웰스토리 | C32: 사내식당 이용 금액 | D32: KRW | F32: 216000
A33: 식당운영비 | B33: 카페어썸 | C33: 사내카페 이용 금액 | D33: KRW | F33: 13700
A34: 식당운영비 | B34: 카페테리아 어썸 | C34: 야간매점 이용 금액 | D34: KRW
A35: 기타 | B35: 에스케이쉴더스 | C35: 사내보안 월정료 | D35: KRW
A36: 기타 | B36: 신도네트웍스 | C36: 복합기 임차료 | D36: KRW
A37: 기타 | B37: LG U+ | C37: 사내 인터넷전화 이용 금액 | D37: KRW | F37: 3157
A38: 기타 | B38: 비전가 | C38: 사내 비데 유지보수 | D38: KRW
A39: 기타 | B39: 느루정(주식회사 영석) | C39: 26년 외부 거래처 설날 선물 지급의 건 | D39: KRW
A40: 기타 | B40: 고위드 | C40: 퀵 운반비 이용 금액 | D40: KRW | F40: 20350
A41: 복리후생비 | B41: 브이아이피버스 | C41: 통근버스 이용 금액 | D41: KRW
...

Sheet 2022년 자금실적
A1: 2022년 컴투버스 자금수지 실적
B7: ※ 2022년 4월 1일 설립 | T7: (단위 : 억원)
B8: 구분 | F8: 2022년 | T8: 세부사항
F9: 1월 | G9: 2월 | H9: 3월 | I9: 4월 | J9: 5월 | K9: 6월 | L9: 7월 | M9: 8월 | N9: 9월 | O9: 10월 | P9: 11월 | Q9: 12월 | R9: 합계 | S9: 월평균
B10: A. 기초잔고 | F10: 0 | G10: =F41 -> 0 | H10: =G41 -> 0 | I10: =H41 -> 0 | J10: =I41 -> 145.92 | K10: =J41 -> 140.60398 | L10: =K41 -> 132.40663 | M10: =L41 -> 111.91968 | N10: =M41 -> 101.27779 | ... Q10: =P41 -> 144.13111 | R10: =F10 -> 0 | S10: =R10/9 -> 0
B11: B. 수입 | F11: =SUM(F12:F14) -> 0 | G11: =SUM(G12:G14) -> 0 | H11: =SUM(H12:H14) -> 0 | I11: =SUM(I12:I14) -> 0 | J11: =SUM(J12:J14) -> 0 | K11: =SUM(K12:K14) -> 0.20207258 | L11: =SUM(L12:L14) -> 0.22 | M11: =SUM(M12:M14) -> 1.6513174 | ... Q11: =SUM(Q12:Q14) -> 0.77390841 | R11: =SUM(R12,R14) -> 3.1812684 | S11: =R11/9 -> 0.35347427
C12: 경상 | I12: 0 | J12: 0 | K12: 0.20207258 | L12: 0 | M12: 0 | N12: 0.33293501 | O12: 0 | P12: 0 | Q12: 0.49694445 | R12: 1.031952 | S12: 0.11466134 | T12: ○ 이자수익
C14: 비경상 | F14: 0 | G14: 0 | H14: 0 | I14: 0 | J14: 0 | K14: 0 | L14: 0.22 | M14: 1.6513174 | N14: 0.001035 | O14: 0 | P14: 0 | Q14: 0.27696396 | R14: 2.1493164 | S14: 0.23881293 | T14: ○ 8월 : 부가가치세 환급 1.7억
B16: C. 지출 | F16: =SUM(F17,F30) -> 0 | G16: =SUM(G17,G30) -> 0 | H16: =SUM(H17,H30) -> 0 | I16: 4.08 | J16: 5.3160247 | K16: 8.399416 | L16: 20.706949 | M16: 12.293211 | N16: 11.859373 | O16: 13.528439 | P16: 12.092835 | Q16: 12.924097 | R16: =SUM(R17,R30) -> 101.20035 | S16: =R16/9 -> 11.244483
C17: 경상 | I17: =I16-I30 -> 3.15 | J17: =J16-J30 -> 4.2960247 | K17: =K16-K30 -> 6.209416 | L17: =L16-L30 -> 8.1869491 | M17: =M16-M30 -> 12.293211 | N17: =N16-N30 -> 11.399373 | O17: =O16-O30 -> 11.558439 | P17: =P16-P30 -> 12.092835 | Q17: =Q16-Q30 -> 12.484097 | R17: =SUM(F17:Q17) -> 81.670346 | S17: =R17/9 -> 9.0744829
D18: 인건비 | I18: 2.33 | J18: 3.5830717 | K18: 3.9665967 | L18: 4.6375612 | M18: 5.2415973 | N18: 6.2017018 | O18: 6.4086734 | P18: 7.7378274 | Q18: 8.4500645 | R18: 48.557094 | S18: 5.3952327
D19: S/W, H/W 매입 | I19: 0 | J19: 0.07 | K19: 0.49 | L19: 0.64 | M19: 4.3 | N19: 1.33 | O19: 0.8 | P19: 1.49 | Q19: 1.36 | R19: 10.48 | S19: 1.1644444
D20: 기타 | I20: =I17-SUM(I18:I19) -> 0.82 | J20: =J17-SUM(J18:J19) -> 0.64295298 | K20: =K17-SUM(K18:K19) -> 1.7528193 | L20: =L17-SUM(L18:L19) -> 2.9093879 | M20: =M17-SUM(M18:M19) -> 2.7516141 | N20: =N17-SUM(N18:N19) -> 3.8676715 | O20: =O17-SUM(O18:O19) -> 4.349766 | P20: =P17-SUM(P18:P19) -> 2.8650079 | Q20: =Q17-SUM(Q18:Q19) -> 2.6740325 | R20: =SUM(I20:Q20) -> 22.633252 | S20: =R20/9 -> 2.5148058
E21: 제세공과금 | I21: 0.72 | J21: 0.36 | K21: 0.49 | L21: 0.45 | M21: 0.51 | N21: 0.53 | O21: 0.68 | P21: 0.72 | Q21: 0.88 | R21: =SUM(I21:Q21) -> 5.34 | S21: =R21/9 -> 0.59333333 | T21: ○ 4월 : 법인등기 영리법인 설립 등록면허세(컴투스 대납분)
E22: 전산관련지출 | K22: 0.03 | L22: 0.03 | M22: 0.06 | N22: 0.16 | O22: 0.19 | P22: 0.31 | Q22: 0.4 | R22: =SUM(I22:Q22) -> 1.18 | S22: =R22/9 -> 0.13111111
E23: 경영, 업무지원, 운영용역비 | L23: 0.29 | M23: 0.5 | N23: 2.05 | O23: 1.15 | P23: 0.6 | Q23: 0.25 | R23: =SUM(I23:Q23) -> 4.84 | S23: =R23/9 -> 0.53777778
E24: 복리후생비 | J24: 0.06 | K24: 0.085 | L24: 0.099 | M24: 0.154 | N24: 0.21 | O24: 0.183 | P24: 0.118 | Q24: 0.264 | R24: =SUM(I24:Q24) -> 1.173 | S24: =R24/9 -> 0.13033333 | T24: ○ 동호회비, 건강검진비용, 명절 선물대금 등
E25: 식당, 카페, 매점 등 운영비 | J25: 0.06 | K25: 0.085 | L25: 0.099 | M25: 0.154 | N25: 0.21 | O25: 0.183 | P25: 0.178 | Q25: 0.264 | R25: =SUM(I25:Q25) -> 1.233 | S25: =R25/9 -> 0.137
E26: 직원비용, 복지포인트 사용비 | J26: 0.07 | K26: 0.25 | L26: 0.34 | M26: 0.37 | N26: 0.268 | O26: 0.32 | P26: 0.38 | Q26: 0.428 | R26: =SUM(I26:Q26) -> 2.426 | S26: =R26/9 -> 0.26955556
E27: 임차료, 관리비 | I27: 0.04 | J27: 0.046 | K27: 0.144 | L27: 0.145 | M27: 0.146 | N27: 0.147 | O27: 0.149 | P27: 0.15 | Q27: 0.16 | R27: =SUM(I27:Q27) -> 1.127 | S27: =R27/9 -> 0.12522222
E28: 지급수수료 | K28: 0.5 | L28: 0.99 | N28: 0.06 | R28: =SUM(I28:Q28) -> 1.55 | S28: =R28/9 -> 0.17222222 | T28: ○ 7월: 메타버스 정보보호 컨설팅수수료 0.99백만
